Workbook

Sheet TRN-LoadFactor-computation
A1: LOAD FACTOR COMPUTATION
A3: 1. Data to be applied
A4: Country | B4: GCAM_region_name | C4: Abreviation | D4: Vehicle occupancy rate | E4: 2015 | F4: 2020 | G4: 2025 | H4: 2030 | I4: 2035 | J4: 2040 | K4: 2045 | L4: 2050
A5: Austria | B5: EU-15 | C5: AT | D5: Average number of people per vehicle | E5: 1.54 | F5: 1.58 | G5: 1.68 | H5: 1.77 | I5: 1.87 | J5: 1.91 | K5: 1.93 | L5: 1.95
A6: Belgium | B6: EU-15 | C6: BE | D6: Average number of people per vehicle | E6: 1.16 | F6: 1.25 | G6: 1.4 | H6: 1.72 | I6: 1.82 | J6: 1.9 | K6: 1.95 | L6: 2
A7: Bulgaria | B7: EU-12 | C7: BG | D7: Average number of people per vehicle | E7: 1.54 | F7: 1.58 | G7: 1.68 | H7: 1.77 | I7: 1.87 | J7: 1.91 | K7: 1.93 | L7: 1.95
A8: Switzerland | C8: CH | D8: Average number of people per vehicle | E8: 1.54 | F8: 1.58 | G8: 1.68 | H8: 1.77 | I8: 1.87 | J8: 1.91 | K8: 1.93 | L8: 1.95
A9: Cyprus | B9: EU-12 | C9: CY | D9: Average number of people per vehicle | E9: 1.54 | F9: 1.58 | G9: 1.68 | H9: 1.77 | I9: 1.87 | J9: 1.91 | K9: 1.93 | L9: 1.95
A10: Czech Republic | B10: EU-12 | C10: CZ | D10: Average number of people per vehicle | E10: 1.54 | F10: 1.58 | G10: 1.68 | H10: 1.77 | I10: 1.87 | J10: 1.91 | K10: 1.93 | L10: 1.95
A11: Germany | B11: EU-15 | C11: DE | D11: Average number of people per vehicle | E11: 1.5 | F11: 1.58 | G11: 1.69 | H11: 1.8 | I11: 1.88 | J11: 1.91 | K11: 1.93 | L11: 1.95
A12: Denmark | B12: EU-15 | C12: DK | D12: Average number of people per vehicle | E12: 1.49 | F12: 1.5 | G12: 1.5 | H12: 1.5 | I12: 1.58 | J12: 1.65 | K12: 1.72 | L12: 1.8
A13: Estonia | B13: EU-12 | C13: EE | D13: Average number of people per vehicle | E13: 1.54 | F13: 1.58 | G13: 1.68 | H13: 1.77 | I13: 1.87 | J13: 1.91 | K13: 1.93 | L13: 1.95
A14: Greece | B14: EU-15 | C14: EL | D14: Average number of people per vehicle | E14: 2.1 | F14: 2.1 | G14: 2.1 | H14: 2.1 | I14: 2.1 | J14: 2.1 | K14: 2.1 | L14: 2.1
A15: Spain | B15: EU-15 | C15: ES | D15: Average number of people per vehicle | E15: 1.45 | F15: 1.45 | G15: 1.61 | H15: 1.72 | I15: 1.83 | J15: 1.88 | K15: 1.9 | L15: 1.9
A16: Finland | B16: EU-15 | C16: FI | D16: Average number of people per vehicle | E16: 1.54 | F16: 1.58 | G16: 1.68 | H16: 1.77 | I16: 1.87 | J16: 1.91 | K16: 1.93 | L16: 1.95
A17: France | B17: EU-15 | C17: FR | D17: Average number of people per vehicle | E17: 1.58 | F17: 1.69 | G17: 1.83 | H17: 1.94 | I17: 2.01 | J17: 2.08 | K17: 2.04 | L17: 2.03
A18: Croatia | B18: EU-12 | C18: HR | D18: Average number of people per vehicle | E18: 1.54 | F18: 1.58 | G18: 1.68 | H18: 1.77 | I18: 1.87 | J18: 1.91 | K18: 1.93 | L18: 1.95
A19: Hungary | B19: EU-12 | C19: HU | D19: Average number of people per vehicle | E19: 1.54 | F19: 1.58 | G19: 1.68 | H19: 1.77 | I19: 1.87 | J19: 1.91 | K19: 1.93 | L19: 1.95
A20: Ireland | B20: EU-15 | C20: IE | D20: Average number of people per vehicle | E20: 1.54 | F20: 1.58 | G20: 1.68 | H20: 1.77 | I20: 1.87 | J20: 1.91 | K20: 1.93 | L20: 1.95
... A26: Netherlands | B26: EU-15 | C26: NL | D26: Average number of people per vehicle | E26: 1.54 | F26: 1.58 | G26: 1.68 | H26: 1.77 | I26: 1.87 | J26: 1.91 | K26: 1.93 | L26: 1.95
A27: Norway | C27: NO | D27: Average number of people per vehicle | E27: 1.54 | F27: 1.58 | G27: 1.68 | H27: 1.77 | I27: 1.87 | J27: 1.91 | K27: 1.93 | L27: 1.95
A28: Poland | B28: EU-12 | C28: PL | D28: Average number of people per vehicle | E28: 1.54 | F28: 1.58 | G28: 1.68 | H28: 1.77 | I28: 1.87 | J28: 1.91 | K28: 1.93 | L28: 1.95
A29: Portugal | B29: EU-15 | C29: PT | D29: Average number of people per vehicle | E29: 1.54 | F29: 1.58 | G29: 1.68 | H29: 1.77 | I29: 1.87 | J29: 1.91 | K29: 1.93 | L29: 1.95
A30: Romania | B30: EU-12 | C30: RO | D30: Average number of people per vehicle | E30: 1.54 | F30: 1.58 | G30: 1.68 | H30: 1.77 | I30: 1.87 | J30: 1.91 | K30: 1.93 | L30: 1.95
A31: Sweden | B31: EU-15 | C31: SE | D31: Average number of people per vehicle | E31: 1.39 | F31: 1.41 | G31: 1.56 | H31: 1.75 | I31: 1.85 | J31: 1.9 | K31: 1.9 | L31: 1.9
A32: Slovenia | B32: EU-12 | C32: SI | D32: Average number of people per vehicle | E32: 1.54 | F32: 1.58 | G32: 1.68 | H32: 1.77 | I32: 1.87 | J32: 1.91 | K32: 1.93 | L32: 1.95
A33: Slovakia | B33: EU-12 | C33: SK | D33: Average number of people per vehicle | E33: 1.54 | F33: 1.58 | G33: 1.68 | H33: 1.77 | I33: 1.87 | J33: 1.91 | K33: 1.93 | L33: 1.95
A34: United Kingdom | C34: UK | D34: Average number of people per vehicle | E34: 1.54 | F34: 1.58 | G34: 1.68 | H34: 1.77 | I34: 1.87 | J34: 1.91 | K34: 1.93 | L34: 1.95
A37: 2. Average values by GCAM region
A38: GCAM_region_name | E38: 2015 | F38: 2020 | G38: 2025 | H38: 2030 | I38: 2035 | J38: 2040 | K38: 2045 | L38: 2050
A39: EU-12 | E39: =SUMIF($B$5:$B$34, $A$39, E5:E34)/ COUNTIF($B$5:$B$34, $A$39) -> 1.5484615 | F39: =SUMIF($B$5:$B$34, $A$39, F5:F34)/ COUNTIF($B$5:$B$34, $A$39) -> 1.5853846 | G39: =SUMIF($B$5:$B$34, $A$39, G5:G34)/ COUNTIF($B$5:$B$34, $A$39) -> 1.6823077 | H39: =SUMIF($B$5:$B$34, $A$39, H5:H34)/ COUNTIF($B$5:$B$34, $A$39) -> 1.7723077 | I39: =SUMIF($B$5:$B$34, $A$39, I5:I34)/ COUNTIF($B$5:$B$34, $A$39) -> 1.8692308 | J39: =SUMIF($B$5:$B$34, $A$39, J5:J34)/ COUNTIF($B$5:$B$34, $A$39) -> 1.9084615 | K39: =SUMIF($B$5:$B$34, $A$39, K5:K34)/ COUNTIF($B$5:$B$34, $A$39) -> 1.9276923 | L39: =SUMIF($B$5:$B$34, $A$39, L5:L34)/ COUNTIF($B$5:$B$34, $A$39) -> 1.9461538
A40: EU-15 | E40: =SUMIF($B$5:$B$34, $A$40, E6:E35)/COUNTIF($B$5:$B$34, $A$40) -> 1.5135714 | F40: =SUMIF($B$5:$B$34, $A$40, F6:F35)/COUNTIF($B$5:$B$34, $A$40) -> 1.5542857 | G40: =SUMIF($B$5:$B$34, $A$40, G6:G35)/COUNTIF($B$5:$B$34, $A$40) -> 1.655 | H40: =SUMIF($B$5:$B$34, $A$40, H6:H35)/COUNTIF($B$5:$B$34, $A$40) -> 1.7578571 | I40: =SUMIF($B$5:$B$34, $A$40, I6:I35)/COUNTIF($B$5:$B$34, $A$40) -> 1.8521429 | J40: =SUMIF($B$5:$B$34, $A$40, J6:J35)/COUNTIF($B$5:$B$34, $A$40) -> 1.8992857 | K40: =SUMIF($B$5:$B$34, $A$40, K6:K35)/COUNTIF($B$5:$B$34, $A$40) -> 1.92 | L40: =SUMIF($B$5:$B$34, $A$40, L6:L35)/COUNTIF($B$5:$B$34, $A$40) -> 1.9414286
A43: 3. Load factor change by period
A44: GCAM_region_name | E44: 2015 | F44: 2020 | G44: 2025 | H44: 2030 | I44: 2035 | J44: 2040 | K44: 2045 | L44: 2050
A45: EU-12 | E45: 1 | F45: =100*(F39-E39)/E39 -> 2.3845007 | G45: =100*(G39-F39)/F39 -> 6.1135371 | H45: =100*(H39-G39)/G39 -> 5.3497942 | I45: =100*(I39-H39)/H39 -> 5.46875 | J45: =100*(J39-I39)/I39 -> 2.0987654 | K45: =100*(K39-J39)/J39 -> 1.0076582 | L45: =100*(L39-K39)/K39 -> 0.95770152
A46: EU-15 | E46: 1 | F46: =100*(F40-E40)/E40 -> 2.6899481 | G46: =100*(G40-F40)/F40 -> 6.4797794 | H46: =100*(H40-G40)/G40 -> 6.2149331 | I46: =100*(I40-H40)/H40 -> 5.3636733 | J46: =100*(J40-I40)/I40 -> 2.5453143 | K46: =100*(K40-J40)/J40 -> 1.0906356 | L46: =100*(L40-K40)/K40 -> 1.1160714
A49: 4. Reshape
A50: region | B50: year | C50: changeRate | D50: NOTE: changeRate for H scenario; halft of the changeRate for low scen
A51: {=INDEX($A$45:$A$46, INT((ROW()-ROW($A$50))/8)+1)} -> EU-12 | B51: {=INDEX($E$44:L$44, MOD(ROW()-ROW($B$50), 8)+1)} -> 2020 | C51: {=INDEX($E$45:$L$46, INT((ROW()-ROW($C$50))/8)+1, MOD(ROW()-ROW($C$50), 8)+1)} -> 2.3845007
A52: {=INDEX($A$45:$A$46, INT((ROW()-ROW($A$50))/8)+1)} -> EU-12 | B52: {=INDEX($E$44:L$44, MOD(ROW()-ROW($B$50), 8)+1)} -> 2025 | C52: {=INDEX($E$45:$L$46, INT((ROW()-ROW($C$50))/8)+1, MOD(ROW()-ROW($C$50), 8)+1)} -> 6.1135371
...

Sheet TRN-LoadFactor-values
A1: {='TRN-LoadFactor-computation'!A50:C65} -> region | B1: year | C1: changeRate
A2: EU-12 | B2: 2020 | C2: 2.3845007
A3: EU-12 | B3: 2025 | C3: 6.1135371
A4: EU-12 | B4: 2030 | C4: 5.3497942
A5: EU-12 | B5: 2035 | C5: 5.46875
A6: EU-12 | B6: 2040 | C6: 2.0987654
A7: EU-12 | B7: 2045 | C7: 1.0076582
A8: EU-12 | B8: 2050 | C8: 0.95770152
A9: EU-15 | B9: 2015 | C9: 1
A10: EU-15 | B10: 2020 | C10: 2.6899481
A11: EU-15 | B11: 2025 | C11: 6.4797794
A12: EU-15 | B12: 2030 | C12: 6.2149331
A13: EU-15 | B13: 2035 | C13: 5.3636733
... A16: EU-15 | B16: 2050 | C16: 1.1160714

Sheet TRN-Modes-computation-IntAv
A1: MODES COMPUTATION
A3: 1. Data from GCAM (LoadFactor Hscen)
A4: transport service output by mode
A5: scenario | B5: region | C5: sector | D5: mode | E5: 1990 | F5: 2005 | G5: 2010 | H5: 2015 | I5: 2020 | J5: 2025 | K5: 2030 | L5: 2035 | M5: 2040 | N5: 2045 | O5: 2050 | P5: 2065 | Q5: 2080 | R5: 2095 | S5: Units
A6: Calib_TRN_LoadFactor_L,date=2025-29-4T09:25:57+02:00 | B6: EU-12 | C6: trn_aviation_intl | D6: International Aviation | E6: 32280.9 | F6: 34737.6 | G6: 41232.1 | H6: 44763.7 | I6: 51257.6 | J6: 64215.1 | K6: 74526.8 | L6: 80474.946 | M6: 84869.263 | N6: 87861.08 | O6: 90268.745 | P6: 0 | Q6: 0 | R6: 0 | S6: million pass-km
A7: Calib_TRN_LoadFactor_L,date=2025-29-4T09:25:57+02:00 | B7: EU-12 | C7: trn_freight | D7: Domestic Ship | E7: 70700.7 | F7: 13111.1 | G7: 17363.7 | H7: 15470.5 | I7: 18041.241 | J7: 21665.5 | K7: 26478.3 | L7: 32704.992 | M7: 36349.689 | N7: 38246.963 | O7: 39723.06 | P7: 0 | Q7: 0 | R7: 0 | S7: million ton-km
A8: Calib_TRN_LoadFactor_L,date=2025-29-4T09:25:57+02:00 | B8: EU-12 | C8: trn_freight | D8: Freight Rail | E8: 262042.36 | F8: 198205.21 | G8: 175160.2 | H8: 164781.04 | I8: 183270.9 | J8: 203256.74 | K8: 200245.7 | L8: 178410 | M8: 171664.7 | N8: 175516.8 | O8: 181839 | P8: 0 | Q8: 0 | R8: 0 | S8: million ton-km
A9: Calib_TRN_LoadFactor_L,date=2025-29-4T09:25:57+02:00 | B9: EU-12 | C9: trn_freight | D9: road | E9: 263310 | F9: 397360 | G9: 479298 | H9: 494165 | I9: 545559 | J9: 614383 | K9: 688777 | L9: 758088 | M9: 809208 | N9: 841895 | O9: 866215 | P9: 0 | Q9: 0 | R9: 0 | S9: million ton-km
A10: Calib_TRN_LoadFactor_L,date=2025-29-4T09:25:57+02:00 | B10: EU-12 | C10: trn_freight_road | D10: Heavy truck | E10: 233530 | F10: 354422 | G10: 427651 | H10: 440708 | I10: 486592.3 | J10: 547591.38 | K10: 613341.81 | L10: 674813.26 | M10: 720315.35 | N10: 749151.13 | O10: 769995.49 | P10: 0 | Q10: 0 | R10: 0 | S10: million ton-km
A11: Calib_TRN_LoadFactor_L,date=2025-29-4T09:25:57+02:00 | B11: EU-12 | C11: trn_freight_road | D11: Light truck | E11: 6938.53 | F11: 8895.31 | G11: 10510.8 | H11: 10995.6 | I11: 12126.824 | J11: 13722.014 | K11: 15470.225 | L11: 17081.636 | M11: 18234.816 | N11: 18968.231 | O11: 19543.096 | P11: 0 | Q11: 0 | R11: 0 | S11: million ton-km
A12: Calib_TRN_LoadFactor_L,date=2025-29-4T09:25:57+02:00 | B12: EU-12 | C12: trn_freight_road | D12: Medium truck | E12: 22841.6 | F12: 34042.9 | G12: 41136.2 | H12: 42461.6 | I12: 46840.1 | J12: 53072.851 | K12: 59975.555 | L12: 66214.517 | M12: 70688.175 | N12: 73812.504 | O12: 76719.865 | P12: 0 | Q12: 0 | R12: 0 | S12: million ton-km
A13: Calib_TRN_LoadFactor_L,date=2025-29-4T09:25:57+02:00 | B13: EU-12 | C13: trn_pass | D13: Cycle | E13: 17265.8 | F13: 16531.9 | G13: 16277.9 | H13: 16023.9 | I13: 14530.4 | J13: 13040.6 | K13: 11654.2 | L13: 10622.6 | M13: 9916.58 | N13: 9355.78 | O13: 8880.15 | P13: 0 | Q13: 0 | R13: 0 | S13: million pass-km
A14: Calib_TRN_LoadFactor_L,date=2025-29-4T09:25:57+02:00 | B14: EU-12 | C14: trn_pass | D14: Domestic Aviation | E14: 5331.03 | F14: 5193.26 | G14: 5821.69 | H14: 6241.59 | I14: 7625.93 | J14: 10975 | K14: 13988.8 | L14: 15728.391 | M14: 17158.606 | N14: 18125.605 | O14: 18853.443 | P14: 0 | Q14: 0 | R14: 0 | S14: million pass-km
A15: Calib_TRN_LoadFactor_L,date=2025-29-4T09:25:57+02:00 | B15: EU-12 | C15: trn_pass | D15: HSR | E15: 0 | F15: 0 | G15: 0 | H15: 0 | I15: 327.275 | J15: 840.07 | K15: 1490 | L15: 2258.24 | M15: 3144.18 | N15: 4165.96 | O15: 5336.91 | P15: 0 | Q15: 0 | R15: 0 | S15: million pass-km
A16: Calib_TRN_LoadFactor_L,date=2025-29-4T09:25:57+02:00 | B16: EU-12 | C16: trn_pass | D16: Passenger Rail | E16: 88848.87 | F16: 70151.4 | G16: 61930.3 | H16: 57839.1 | I16: 60894.9 | J16: 64288.7 | K16: 64528.5 | L16: 63979.5 | M16: 62936.7 | N16: 61966.7 | O16: 61040 | P16: 0 | Q16: 0 | R16: 0 | S16: million pass-km
... A45: Calib_TRN_LoadFactor_L,date=2025-29-4T09:25:57+02:00 | B45: EU-15 | C45: trn_shipping_intl | D45: International Ship | E45: 12346400 | F45: 18282500 | G45: 16574700 | H45: 14015900 | I45: 14055326 | J45: 14856120 | K45: 15425600 | L45: 16454398 | M45: 17169591 | N45: 17740740 | O45: 18312617 | P45: 0 | Q45: 0 | R45: 0 | S45: million ton-km
A47: income.elasticity | E47: 1990 | F47: 2005 | G47: 2010 | H47: 2015 | I47: 2020 | J47: 2025 | K47: 2030 | L47: 2035 | M47: 2040 | N47: 2045 | O47: 2050 | P47: 2065 | Q47: 2080 | R47: 2095 | S47: Units
B48: EU-12 | C48: trn_aviation_intl | D48: International Aviation | E48: 1 | F48: 1 | G48: 1 | H48: 1 | I48: 1 | J48: 1 | K48: 1 | L48: 1 | M48: 1 | N48: 1 | O48: 1 | S48: unitless
B49: EU-15 | C49: trn_aviation_intl | D49: International Aviation | E49: 1 | F49: 1 | G49: 1 | H49: 1 | I49: 1 | J49: 1 | K49: 1 | L49: 1 | M49: 1 | N49: 1 | O49: 1 | S49: unitless
A51: transport subsector share-weights
A52: scenario | B52: region | C52: sector | D52: subsector | E52: 1990 | F52: 2005 | G52: 2010 | H52: 2015 | I52: 2020 | J52: 2025 | K52: 2030 | L52: 2035 | M52: 2040 | N52: 2045 | O52: 2050 | P52: 2055 | Q52: 2060 | R52: 2065 | S52: 2070 | T52: 2075 | U52: 2080 | V52: 2085 | W52: 2090 | X52: 2095 | Y52: 2100 | Z52: Units
A53: Calib_TRN_LoadFactor_L,date=2025-29-4T09:25:57+02:00 | B53: EU-12 | C53: trn_aviation_intl | D53: International Aviation | E53: 1 | F53: 1 | G53: 1 | H53: 1 | I53: 1 | J53: 1 | K53: 1 | L53: 1 | M53: 1 | N53: 1 | O53: 1 | P53: 1 | Q53: 1 | R53: 1 | S53: 1 | T53: 1 | U53: 1 | V53: 1 | W53: 1 | X53: 1 | Y53: 1 | Z53: none
A54: Calib_TRN_LoadFactor_L,date=2025-29-4T09:25:57+02:00 | B54: EU-12 | C54: trn_freight | D54: Domestic Ship | E54: 0.000795575 | F54: 0.000114108 | G54: 0.000240711 | H54: 0.000229626 | I54: 0.000229626 | J54: 0.000229626 | K54: 0.000229626 | L54: 0.000229626 | M54: 0.000229626 | N54: 0.000229626 | O54: 0.000229626 | P54: 0.000229626 | Q54: 0.000229626 | R54: 0.000229626 | S54: 0.000229626 | T54: 0.000229626 | U54: 0.000229626 | V54: 0.000229626 | W54: 0.000229626 | X54: 0.000229626 | Y54: 0.000229626 | Z54: none
A55: Calib_TRN_LoadFactor_L,date=2025-29-4T09:25:57+02:00 | B55: EU-12 | C55: trn_freight | D55: Freight Rail | E55: 0.201544 | F55: 0.110995 | G55: 0.0710973 | H55: 0.062487 | I55: 0.062487 | J55: 0.062487 | K55: 0.062487 | L55: 0.062487 | M55: 0.062487 | N55: 0.062487 | O55: 0.062487 | P55: 0.062487 | Q55: 0.062487 | R55: 0.062487 | S55: 0.062487 | T55: 0.062487 | U55: 0.062487 | V55: 0.062487 | W55: 0.062487 | X55: 0.062487 | Y55: 0.062487 | Z55: none
A56: Calib_TRN_LoadFactor_L,date=2025-29-4T09:25:57+02:00 | B56: EU-12 | C56: trn_freight | D56: road | E56: 1 | F56: 1 | G56: 1 | H56: 1 | I56: 1 | J56: 1 | K56: 1 | L56: 1 | M56: 1 | N56: 1 | O56: 1 | P56: 1 | Q56: 1 | R56: 1 | S56: 1 | T56: 1 | U56: 1 | V56: 1 | W56: 1 | X56: 1 | Y56: 1 | Z56: none
A57: Calib_TRN_LoadFactor_L,date=2025-29-4T09:25:57+02:00 | B57: EU-12 | C57: trn_freight_road | D57: Heavy truck | E57: 1 | F57: 1 | G57: 1 | H57: 1 | I57: 1 | J57: 1 | K57: 1 | L57: 1 | M57: 1 | N57: 1 | O57: 1 | P57: 1 | Q57: 1 | R57: 1 | S57: 1 | T57: 1 | U57: 1 | V57: 1 | W57: 1 | X57: 1 | Y57: 1 | Z57: none
A58: Calib_TRN_LoadFactor_L,date=2025-29-4T09:25:57+02:00 | B58: EU-12 | C58: trn_freight_road | D58: Light truck | E58: 0.388042 | F58: 0.326507 | G58: 0.295752 | H58: 0.295565 | I58: 0.295565 | J58: 0.295565 | K58: 0.295565 | L58: 0.295565 | M58: 0.295565 | N58: 0.295565 | O58: 0.295565 | P58: 0.295565 | Q58: 0.295565 | R58: 0.295565 | S58: 0.295565 | T58: 0.295565 | U58: 0.295565 | V58: 0.295565 | W58: 0.295565 | X58: 0.295565 | Y58: 0.295565 | Z58: none
A59: Calib_TRN_LoadFactor_L,date=2025-29-4T09:25:57+02:00 | B59: EU-12 | C59: trn_freight_road | D59: Medium truck | E59: 0.499758 | F59: 0.488309 | G59: 0.461901 | H59: 0.457693 | I59: 0.457693 | J59: 0.457693 | K59: 0.457693 | L59: 0.457693 | M59: 0.457693 | N59: 0.457693 | O59: 0.457693 | P59: 0.457693 | Q59: 0.457693 | R59: 0.457693 | S59: 0.457693 | T59: 0.457693 | U59: 0.457693 | V59: 0.457693 | W59: 0.457693 | X59: 0.457693 | Y59: 0.457693 | Z59: none
A60: Calib_TRN_LoadFactor_L,date=2025-29-4T09:25:57+02:00 | B60: EU-12 | C60: trn_pass | D60: Cycle | E60: 0.0150988 | F60: 0.0140179 | G60: 0.0128294 | H60: 0.0137751 | I60: 0.0137751 | J60: 0.0137751 | K60: 0.0137751 | L60: 0.0137751 | M60: 0.0137751 | N60: 0.0137751 | O60: 0.0137751 | P60: 0.0137751 | Q60: 0.0137751 | R60: 0.0137751 | S60: 0.0137751 | T60: 0.0137751 | U60: 0.0137751 | V60: 0.0137751 | W60: 0.0137751 | X60: 0.0137751 | Y60: 0.0137751 | Z60: none
A61: Calib_TRN_LoadFactor_L,date=2025-29-4T09:25:57+02:00 | B61: EU-12 | C61: trn_pass | D61: Domestic Aviation | E61: 0.00257035 | F61: 0.00157745 | G61: 0.0015847 | H61: 0.00149513 | I61: 0.00149513 | J61: 0.00149513 | K61: 0.00149513 | L61: 0.00149513 | M61: 0.00149513 | N61: 0.00149513 | O61: 0.00149513 | P61: 0.00149513 | Q61: 0.00149513 | R61: 0.00149513 | S61: 0.00149513 | T61: 0.00149513 | U61: 0.00149513 | V61: 0.00149513 | W61: 0.00149513 | X61: 0.00149513 | Y61: 0.00149513 | Z61: none
A62: Calib_TRN_LoadFactor_L,date=2025-29-4T09:25:57+02:00 | B62: EU-12 | C62: trn_pass | D62: HSR | E62: 0 | F62: 0 | G62: 0 | H62: 0 | I62: 5.88235e-05 | J62: 0.000117647 | K62: 0.000176471 | L62: 0.000235294 | M62: 0.000294118 | N62: 0.000352941 | O62: 0.000411765 | P62: 0.000470588 | Q62: 0.000529412 | R62: 0.000588235 | S62: 0.000647059 | T62: 0.000705882 | U62: 0.000764706 | V62: 0.000823529 | W62: 0.000882353 | X62: 0.000941176 | Y62: 0.001 | Z62: none
A63: Calib_TRN_LoadFactor_L,date=2025-29-4T09:25:57+02:00 | B63: EU-12 | C63: trn_pass | D63: Passenger Rail | E63: 0.0353507 | F63: 0.020358 | G63: 0.0147021 | H63: 0.0132408 | I63: 0.0132408 | J63: 0.0132408 | K63: 0.0132408 | L63: 0.0132408 | M63: 0.0132408 | N63: 0.0132408 | O63: 0.0132408 | P63: 0.0132408 | Q63: 0.0132408 | R63: 0.0132408 | S63: 0.0132408 | T63: 0.0132408 | U63: 0.0132408 | V63: 0.0132408 | W63: 0.0132408 | X63: 0.0132408 | Y63: 0.0132408 | Z63: none
... A92: Calib_TRN_LoadFactor_L,date=2025-29-4T09:25:57+02:00 | B92: EU-15 | C92: trn_shipping_intl | D92: International Ship | E92: 1 | F92: 1 | G92: 1 | H92: 1 | I92: 1 | J92: 1 | K92: 1 | L92: 1 | M92: 1 | N92: 1 | O92: 1 | P92: 1 | Q92: 1 | R92: 1 | S92: 1 | T92: 1 | U92: 1 | V92: 1 | W92: 1 | X92: 1 | Y92: 1 | Z92: none
A95: 2. Data to be applied
A96: mode | B96: ctry | C96: 2015 | D96: 2020 | E96: 2050 | F96: GCAM_region_ID | G96: Unit
A97: NMT | B97: AUSTRIA | C97: 0.0692 | D97: 0.07 | E97: 0.1345 | F97: 13 | G97: Perc
A98: NMT | B98: BELGIUM | C98: 0.0523 | D98: 0.0562 | E98: 0.1345 | F98: 13 | G98: Perc
A99: NMT | B99: BULGARIA | C99: 0.0768 | D99: 0.0776 | E99: 0.0755 | F99: 12 | G99: Perc
A100: NMT | B100: CROATIA | C100: 0.074 | D100: 0.074 | E100: 0.0755 | F100: 12 | G100: Perc
A101: NMT | B101: CYPRUS | C101: 0.0426 | D101: 0.0436 | E101: 0.0437 | F101: 12 | G101: Perc
...

Sheet TRN-Modes-values-IntAv
A1: region | B1: {='TRN-Modes-computation-IntAv'!J283:Q283} -> 2015 | C1: 2020 | D1: 2025 | E1: 2030 | F1: 2035 | G1: 2040 | H1: 2045 | I1: 2050 | J1: energy.final.demand
A2: {='TRN-Modes-computation-IntAv'!I285:Q285} -> EU-12 | B2: 1 | C2: 1 | D2: 0.065659783 | E2: 0.065659783 | F2: 0.065659783 | G2: 0.065659783 | H2: 0.065659783 | I2: 0.065659783 | J2: trn_aviation_intl
A3: {='TRN-Modes-computation-IntAv'!I289:Q289} -> EU-15 | B3: 1 | C3: 1 | D3: -0.75390036 | E3: -0.75390036 | F3: -0.75390036 | G3: -0.75390036 | H3: -0.75390036 | I3: -0.75390036 | J3: trn_aviation_intl

Sheet TRN-Modes-computation-SW
A1: MODES COMPUTATION
A3: 1. Data from GCAM (LoadFactor Hscen)
A4: transport service output by mode
A5: scenario | B5: region | C5: sector | D5: mode | E5: 1990 | F5: 2005 | G5: 2010 | H5: 2015 | I5: 2020 | J5: 2025 | K5: 2030 | L5: 2035 | M5: 2040 | N5: 2045 | O5: 2050 | P5: 2065 | Q5: 2080 | R5: 2095 | S5: Units
A6: Calib_TRN_IntAv_L,date=2025-29-4T10:22:36+02:00 | B6: EU-12 | C6: trn_aviation_intl | D6: International Aviation | E6: 32280.9 | F6: 34737.6 | G6: 41232.1 | H6: 44763.7 | I6: 51257.6 | J6: 54343.3 | K6: 54438.1 | L6: 52491.03 | M6: 50556.194 | N6: 48832.063 | O6: 47340.197 | P6: 0 | Q6: 0 | R6: 0 | S6: million pass-km
A7: Calib_TRN_IntAv_L,date=2025-29-4T10:22:36+02:00 | B7: EU-12 | C7: trn_freight | D7: Domestic Ship | E7: 70700.7 | F7: 13111.1 | G7: 17363.7 | H7: 15470.5 | I7: 18041.241 | J7: 21673.21 | K7: 26499.7 | L7: 32737.437 | M7: 36393.296 | N7: 38293.992 | O7: 39769.738 | P7: 0 | Q7: 0 | R7: 0 | S7: million ton-km
A8: Calib_TRN_IntAv_L,date=2025-29-4T10:22:36+02:00 | B8: EU-12 | C8: trn_freight | D8: Freight Rail | E8: 262042.36 | F8: 198205.21 | G8: 175160.2 | H8: 164781.04 | I8: 183270.9 | J8: 203243.18 | K8: 200213 | L8: 178374 | M8: 171623.6 | N8: 175474.2 | O8: 181797.7 | P8: 0 | Q8: 0 | R8: 0 | S8: million ton-km
A9: Calib_TRN_IntAv_L,date=2025-29-4T10:22:36+02:00 | B9: EU-12 | C9: trn_freight | D9: road | E9: 263310 | F9: 397360 | G9: 479298 | H9: 494165 | I9: 545559 | J9: 614422 | K9: 688875 | L9: 758215 | M9: 809364 | N9: 842059 | O9: 866374 | P9: 0 | Q9: 0 | R9: 0 | S9: million ton-km
A10: Calib_TRN_IntAv_L,date=2025-29-4T10:22:36+02:00 | B10: EU-12 | C10: trn_freight_road | D10: Heavy truck | E10: 233530 | F10: 354422 | G10: 427651 | H10: 440708 | I10: 486592.3 | J10: 547626.48 | K10: 613432.15 | L10: 674932.84 | M10: 720464.35 | N10: 749310.96 | O10: 770153.35 | P10: 0 | Q10: 0 | R10: 0 | S10: million ton-km
A11: Calib_TRN_IntAv_L,date=2025-29-4T10:22:36+02:00 | B11: EU-12 | C11: trn_freight_road | D11: Light truck | E11: 6938.53 | F11: 8895.31 | G11: 10510.8 | H11: 10995.6 | I11: 12126.824 | J11: 13722.636 | K11: 15471.48 | L11: 17082.471 | M11: 18235.5 | N11: 18968.472 | O11: 19542.933 | P11: 0 | Q11: 0 | R11: 0 | S11: million ton-km
A12: Calib_TRN_IntAv_L,date=2025-29-4T10:22:36+02:00 | B12: EU-12 | C12: trn_freight_road | D12: Medium truck | E12: 22841.6 | F12: 34042.9 | G12: 41136.2 | H12: 42461.6 | I12: 46840.1 | J12: 53075.599 | K12: 59981.743 | L12: 66220.431 | M12: 70694.292 | N12: 73817.015 | O12: 76722.454 | P12: 0 | Q12: 0 | R12: 0 | S12: million ton-km
A13: Calib_TRN_IntAv_L,date=2025-29-4T10:22:36+02:00 | B13: EU-12 | C13: trn_pass | D13: Cycle | E13: 17265.8 | F13: 16531.9 | G13: 16277.9 | H13: 16023.9 | I13: 14530.4 | J13: 13040.5 | K13: 11654.1 | L13: 10622.4 | M13: 9916.45 | N13: 9355.67 | O13: 8880.07 | P13: 0 | Q13: 0 | R13: 0 | S13: million pass-km
A14: Calib_TRN_IntAv_L,date=2025-29-4T10:22:36+02:00 | B14: EU-12 | C14: trn_pass | D14: Domestic Aviation | E14: 5331.03 | F14: 5193.26 | G14: 5821.69 | H14: 6241.59 | I14: 7625.93 | J14: 10976.6 | K14: 13993.3 | L14: 15734.048 | M14: 17165.87 | N14: 18133.148 | O14: 18860.61 | P14: 0 | Q14: 0 | R14: 0 | S14: million pass-km
A15: Calib_TRN_IntAv_L,date=2025-29-4T10:22:36+02:00 | B15: EU-12 | C15: trn_pass | D15: HSR | E15: 0 | F15: 0 | G15: 0 | H15: 0 | I15: 327.275 | J15: 840.064 | K15: 1489.98 | L15: 2258.21 | M15: 3144.15 | N15: 4165.93 | O15: 5336.89 | P15: 0 | Q15: 0 | R15: 0 | S15: million pass-km
A16: Calib_TRN_IntAv_L,date=2025-29-4T10:22:36+02:00 | B16: EU-12 | C16: trn_pass | D16: Passenger Rail | E16: 88848.87 | F16: 70151.4 | G16: 61930.3 | H16: 57839.1 | I16: 60894.9 | J16: 64288.9 | K16: 64529.2 | L16: 63980.4 | M16: 62937.7 | N16: 61967.8 | O16: 61041 | P16: 0 | Q16: 0 | R16: 0 | S16: million pass-km
... A45: Calib_TRN_IntAv_L,date=2025-29-4T10:22:36+02:00 | B45: EU-15 | C45: trn_shipping_intl | D45: International Ship | E45: 12346400 | F45: 18282500 | G45: 16574700 | H45: 14015900 | I45: 14055326 | J45: 14857700 | K45: 15429090 | L45: 16458252 | M45: 17174807 | N45: 17745489 | O45: 18316869 | P45: 0 | Q45: 0 | R45: 0 | S45: million ton-km
A47: income.elasticity | E47: 1990 | F47: 2005 | G47: 2010 | H47: 2015 | I47: 2020 | J47: 2025 | K47: 2030 | L47: 2035 | M47: 2040 | N47: 2045 | O47: 2050 | P47: 2065 | Q47: 2080 | R47: 2095 | S47: Units
B48: EU-12 | C48: trn_aviation_intl | D48: International Aviation | E48: 1 | F48: 1 | G48: 1 | H48: 1 | I48: 1 | J48: 1 | K48: 1 | L48: 1 | M48: 1 | N48: 1 | O48: 1 | S48: unitless
B49: EU-15 | C49: trn_aviation_intl | D49: International Aviation | E49: 1 | F49: 1 | G49: 1 | H49: 1 | I49: 1 | J49: 1 | K49: 1 | L49: 1 | M49: 1 | N49: 1 | O49: 1 | S49: unitless
A51: transport subsector share-weights
A52: scenario | B52: region | C52: sector | D52: subsector | E52: 1990 | F52: 2005 | G52: 2010 | H52: 2015 | I52: 2020 | J52: 2025 | K52: 2030 | L52: 2035 | M52: 2040 | N52: 2045 | O52: 2050 | P52: 2055 | Q52: 2060 | R52: 2065 | S52: 2070 | T52: 2075 | U52: 2080 | V52: 2085 | W52: 2090 | X52: 2095 | Y52: 2100 | Z52: Units
A53: Calib_TRN_IntAv_L,date=2025-29-4T10:22:36+02:00 | B53: EU-12 | C53: trn_aviation_intl | D53: International Aviation | E53: 1 | F53: 1 | G53: 1 | H53: 1 | I53: 1 | J53: 1 | K53: 1 | L53: 1 | M53: 1 | N53: 1 | O53: 1 | P53: 1 | Q53: 1 | R53: 1 | S53: 1 | T53: 1 | U53: 1 | V53: 1 | W53: 1 | X53: 1 | Y53: 1 | Z53: none
A54: Calib_TRN_IntAv_L,date=2025-29-4T10:22:36+02:00 | B54: EU-12 | C54: trn_freight | D54: Domestic Ship | E54: 0.000795575 | F54: 0.000114108 | G54: 0.000240711 | H54: 0.000229626 | I54: 0.000229626 | J54: 0.000229626 | K54: 0.000229626 | L54: 0.000229626 | M54: 0.000229626 | N54: 0.000229626 | O54: 0.000229626 | P54: 0.000229626 | Q54: 0.000229626 | R54: 0.000229626 | S54: 0.000229626 | T54: 0.000229626 | U54: 0.000229626 | V54: 0.000229626 | W54: 0.000229626 | X54: 0.000229626 | Y54: 0.000229626 | Z54: none
A55: Calib_TRN_IntAv_L,date=2025-29-4T10:22:36+02:00 | B55: EU-12 | C55: trn_freight | D55: Freight Rail | E55: 0.201544 | F55: 0.110995 | G55: 0.0710973 | H55: 0.062487 | I55: 0.062487 | J55: 0.062487 | K55: 0.062487 | L55: 0.062487 | M55: 0.062487 | N55: 0.062487 | O55: 0.062487 | P55: 0.062487 | Q55: 0.062487 | R55: 0.062487 | S55: 0.062487 | T55: 0.062487 | U55: 0.062487 | V55: 0.062487 | W55: 0.062487 | X55: 0.062487 | Y55: 0.062487 | Z55: none
A56: Calib_TRN_IntAv_L,date=2025-29-4T10:22:36+02:00 | B56: EU-12 | C56: trn_freight | D56: road | E56: 1 | F56: 1 | G56: 1 | H56: 1 | I56: 1 | J56: 1 | K56: 1 | L56: 1 | M56: 1 | N56: 1 | O56: 1 | P56: 1 | Q56: 1 | R56: 1 | S56: 1 | T56: 1 | U56: 1 | V56: 1 | W56: 1 | X56: 1 | Y56: 1 | Z56: none
A57: Calib_TRN_IntAv_L,date=2025-29-4T10:22:36+02:00 | B57: EU-12 | C57: trn_freight_road | D57: Heavy truck | E57: 1 | F57: 1 | G57: 1 | H57: 1 | I57: 1 | J57: 1 | K57: 1 | L57: 1 | M57: 1 | N57: 1 | O57: 1 | P57: 1 | Q57: 1 | R57: 1 | S57: 1 | T57: 1 | U57: 1 | V57: 1 | W57: 1 | X57: 1 | Y57: 1 | Z57: none
A58: Calib_TRN_IntAv_L,date=2025-29-4T10:22:36+02:00 | B58: EU-12 | C58: trn_freight_road | D58: Light truck | E58: 0.388042 | F58: 0.326507 | G58: 0.295752 | H58: 0.295565 | I58: 0.295565 | J58: 0.295565 | K58: 0.295565 | L58: 0.295565 | M58: 0.295565 | N58: 0.295565 | O58: 0.295565 | P58: 0.295565 | Q58: 0.295565 | R58: 0.295565 | S58: 0.295565 | T58: 0.295565 | U58: 0.295565 | V58: 0.295565 | W58: 0.295565 | X58: 0.295565 | Y58: 0.295565 | Z58: none
A59: Calib_TRN_IntAv_L,date=2025-29-4T10:22:36+02:00 | B59: EU-12 | C59: trn_freight_road | D59: Medium truck | E59: 0.499758 | F59: 0.488309 | G59: 0.461901 | H59: 0.457693 | I59: 0.457693 | J59: 0.457693 | K59: 0.457693 | L59: 0.457693 | M59: 0.457693 | N59: 0.457693 | O59: 0.457693 | P59: 0.457693 | Q59: 0.457693 | R59: 0.457693 | S59: 0.457693 | T59: 0.457693 | U59: 0.457693 | V59: 0.457693 | W59: 0.457693 | X59: 0.457693 | Y59: 0.457693 | Z59: none
A60: Calib_TRN_IntAv_L,date=2025-29-4T10:22:36+02:00 | B60: EU-12 | C60: trn_pass | D60: Cycle | E60: 0.0150988 | F60: 0.0140179 | G60: 0.0128294 | H60: 0.0137751 | I60: 0.0137751 | J60: 0.0137751 | K60: 0.0137751 | L60: 0.0137751 | M60: 0.0137751 | N60: 0.0137751 | O60: 0.0137751 | P60: 0.0137751 | Q60: 0.0137751 | R60: 0.0137751 | S60: 0.0137751 | T60: 0.0137751 | U60: 0.0137751 | V60: 0.0137751 | W60: 0.0137751 | X60: 0.0137751 | Y60: 0.0137751 | Z60: none
A61: Calib_TRN_IntAv_L,date=2025-29-4T10:22:36+02:00 | B61: EU-12 | C61: trn_pass | D61: Domestic Aviation | E61: 0.00257035 | F61: 0.00157745 | G61: 0.0015847 | H61: 0.00149513 | I61: 0.00149513 | J61: 0.00149513 | K61: 0.00149513 | L61: 0.00149513 | M61: 0.00149513 | N61: 0.00149513 | O61: 0.00149513 | P61: 0.00149513 | Q61: 0.00149513 | R61: 0.00149513 | S61: 0.00149513 | T61: 0.00149513 | U61: 0.00149513 | V61: 0.00149513 | W61: 0.00149513 | X61: 0.00149513 | Y61: 0.00149513 | Z61: none
A62: Calib_TRN_IntAv_L,date=2025-29-4T10:22:36+02:00 | B62: EU-12 | C62: trn_pass | D62: HSR | E62: 0 | F62: 0 | G62: 0 | H62: 0 | I62: 5.88235e-05 | J62: 0.000117647 | K62: 0.000176471 | L62: 0.000235294 | M62: 0.000294118 | N62: 0.000352941 | O62: 0.000411765 | P62: 0.000470588 | Q62: 0.000529412 | R62: 0.000588235 | S62: 0.000647059 | T62: 0.000705882 | U62: 0.000764706 | V62: 0.000823529 | W62: 0.000882353 | X62: 0.000941176 | Y62: 0.001 | Z62: none
A63: Calib_TRN_IntAv_L,date=2025-29-4T10:22:36+02:00 | B63: EU-12 | C63: trn_pass | D63: Passenger Rail | E63: 0.0353507 | F63: 0.020358 | G63: 0.0147021 | H63: 0.0132408 | I63: 0.0132408 | J63: 0.0132408 | K63: 0.0132408 | L63: 0.0132408 | M63: 0.0132408 | N63: 0.0132408 | O63: 0.0132408 | P63: 0.0132408 | Q63: 0.0132408 | R63: 0.0132408 | S63: 0.0132408 | T63: 0.0132408 | U63: 0.0132408 | V63: 0.0132408 | W63: 0.0132408 | X63: 0.0132408 | Y63: 0.0132408 | Z63: none
... A92: Calib_TRN_IntAv_L,date=2025-29-4T10:22:36+02:00 | B92: EU-15 | C92: trn_shipping_intl | D92: International Ship | E92: 1 | F92: 1 | G92: 1 | H92: 1 | I92: 1 | J92: 1 | K92: 1 | L92: 1 | M92: 1 | N92: 1 | O92: 1 | P92: 1 | Q92: 1 | R92: 1 | S92: 1 | T92: 1 | U92: 1 | V92: 1 | W92: 1 | X92: 1 | Y92: 1 | Z92: none
A95: 2. Data to be applied
A96: mode | B96: ctry | C96: 2015 | D96: 2020 | E96: 2050 | F96: GCAM_region_ID | G96: Unit
A97: NMT | B97: AUSTRIA | C97: 0.0692 | D97: 0.07 | E97: 0.1345 | F97: 13 | G97: Perc
A98: NMT | B98: BELGIUM | C98: 0.0523 | D98: 0.0562 | E98: 0.1345 | F98: 13 | G98: Perc
A99: NMT | B99: BULGARIA | C99: 0.0768 | D99: 0.0776 | E99: 0.0755 | F99: 12 | G99: Perc
A100: NMT | B100: CROATIA | C100: 0.074 | D100: 0.074 | E100: 0.0755 | F100: 12 | G100: Perc
A101: NMT | B101: CYPRUS | C101: 0.0426 | D101: 0.0436 | E101: 0.0437 | F101: 12 | G101: Perc
...

Sheet TRN-Modes-values-SW
A1: region | B1: mode | C1: 2015 | D1: 2020 | E1: 2025 | F1: 2030 | G1: 2035 | H1: 2040 | I1: 2045 | J1: 2050 | K1: tranSubsector
A2: EU-12 | B2: {='TRN-Modes-computation-SW'!N304:V311} -> NMT - Cycling | C2: 0.0137751 | D2: 0.0137751 | E2: 0.019413894 | F2: 0.025052688 | G2: 0.030691482 | H2: 0.036330276 | I2: 0.04196907 | J2: 0.047607864 | K2: Cycle
A3: EU-12 | B3: NMT - Walking | C3: 0.403575 | D3: 0.403575 | E3: 0.56877716 | F3: 0.73397933 | G3: 0.89918149 | H3: 1.0643837 | I3: 1.2295858 | J3: 1.394788 | K3: Walk
A4: EU-12 | B4: road - 4W | C4: 1 | D4: 1 | E4: 0.9840461 | F4: 0.9680922 | G4: 0.9521383 | H4: 0.9361844 | I4: 0.9202305 | J4: 0.9042766 | K4: 4W
A5: EU-12 | B5: road - 2-3W | C5: 0.012729 | D5: 0.012729 | E5: 0.012525923 | F5: 0.012322846 | G5: 0.012119768 | H5: 0.011916691 | I5: 0.011713614 | J5: 0.011510537 | K5: 2W and 3W
A6: EU-12 | B6: road - bus | C6: 0.388134 | D6: 0.388134 | E6: 0.38194175 | F6: 0.3757495 | G6: 0.36955725 | H6: 0.363365 | I6: 0.35717274 | J6: 0.35098049 | K6: Bus
A7: EU-12 | B7: trains - HSR | C7: 0 | D7: 5.88235e-05 | E7: 6.3479159e-05 | F7: 6.8134817e-05 | G7: 7.2790476e-05 | H7: 7.7446135e-05 | I7: 8.2101794e-05 | J7: 8.6757452e-05 | K7: HSR
A8: EU-12 | B8: trains - Pass Rail | C8: 0.0132408 | D8: 0.0132408 | E8: 0.01428876 | F8: 0.015336719 | G8: 0.016384679 | H8: 0.017432638 | I8: 0.018480598 | J8: 0.019528557 | K8: Passenger Rail
A9: EU-12 | B9: av - Dom Av | C9: 0.00149513 | D9: 0.00149513 | E9: 0.0012459417 | F9: 0.00099675333 | G9: 0.000747565 | H9: 0.00049837667 | I9: 0.00024918833 | J9: 0 | K9: Domestic Aviation
A10: EU-15 | B10: {='TRN-Modes-computation-SW'!N320:V327} -> NMT - Cycling | C10: 0.0239423 | D10: 0.0239423 | E10: 0.036698093 | F10: 0.049453886 | G10: 0.062209679 | H10: 0.074965472 | I10: 0.087721265 | J10: 0.10047706 | K10: Cycle
A11: EU-15 | B11: NMT - Walking | C11: 0.701434 | D11: 0.701434 | E11: 1.0751386 | F11: 1.4488431 | G11: 1.8225477 | H11: 2.1962523 | I11: 2.5699568 | J11: 2.9436614 | K11: Walk
A12: EU-15 | B12: road - 4W | C12: 1 | D12: 1 | E12: 0.98861729 | F12: 0.97723457 | G12: 0.96585186 | H12: 0.95446915 | I12: 0.94308643 | J12: 0.93170372 | K12: 4W
A13: EU-15 | B13: road - 2-3W | C13: 0.019504 | D13: 0.019504 | E13: 0.019281992 | F13: 0.019059983 | G13: 0.018837975 | H13: 0.018615966 | I13: 0.018393958 | J13: 0.018171949 | K13: 2W and 3W
A14: EU-15 | B14: road - bus | C14: 0.0526778 | D14: 0.0526778 | E14: 0.052078184 | F14: 0.051478567 | G14: 0.050878951 | H14: 0.050279335 | I14: 0.049679718 | J14: 0.049080102 | K14: Bus
A15: EU-15 | B15: trains - HSR | C15: 0.00240216 | D15: 0.00231968 | E15: 0.0024024016 | F15: 0.0024851232 | G15: 0.0025678447 | H15: 0.0026505663 | I15: 0.0027332879 | J15: 0.0028160095 | K15: HSR
A16: EU-15 | B16: trains - Pass Rail | C16: 0.0509634 | D16: 0.0509634 | E16: 0.052780794 | F16: 0.054598188 | G16: 0.056415583 | H16: 0.058232977 | I16: 0.060050371 | J16: 0.061867765 | K16: Passenger Rail
A17: EU-15 | B17: av - Dom Av | C17: 0.00807093 | D17: 0.00807093 | E17: 0.0068364622 | F17: 0.0056019944 | G17: 0.0043675266 | H17: 0.0031330588 | I17: 0.001898591 | J17: 0.00066412315 | K17: Domestic Aviation

Sheet TRN-PassKM-computation
A1: PASS KM COMPUTATION
A3: 1. Data from GCAM (LoadFactor + ModalShares Hscen)
A4: transport service output by mode
A5: scenario | B5: region | C5: sector | D5: mode | E5: 1990 | F5: 2005 | G5: 2010 | H5: 2015 | I5: 2020 | J5: 2025 | K5: 2030 | L5: 2035 | M5: 2040 | N5: 2045 | O5: 2050 | P5: 2065 | Q5: 2080 | R5: 2095 | S5: Units
A6: Calib_TRN_SW_PassKm_L4,date=2025-29-4T16:10:05+02:00 | B6: EU-12 | C6: trn_aviation_intl | D6: International Aviation | E6: 32280.9 | F6: 34737.6 | G6: 41232.1 | H6: 44763.7 | I6: 51257.6 | J6: 54355.7 | K6: 54468.1 | L6: 52524.83 | M6: 50595.193 | N6: 48871.348 | O6: 47373.902 | P6: 0 | Q6: 0 | R6: 0 | S6: million pass-km
A7: Calib_TRN_SW_PassKm_L4,date=2025-29-4T16:10:05+02:00 | B7: EU-12 | C7: trn_freight | D7: Domestic Ship | E7: 70700.7 | F7: 13111.1 | G7: 17363.7 | H7: 15470.5 | I7: 18041.241 | J7: 21699.21 | K7: 26581.7 | L7: 32867.588 | M7: 36574.069 | N7: 38500.135 | O7: 39965.439 | P7: 0 | Q7: 0 | R7: 0 | S7: million ton-km
A8: Calib_TRN_SW_PassKm_L4,date=2025-29-4T16:10:05+02:00 | B8: EU-12 | C8: trn_freight | D8: Freight Rail | E8: 262042.36 | F8: 198205.21 | G8: 175160.2 | H8: 164781.04 | I8: 183270.9 | J8: 203196.98 | K8: 200092.5 | L8: 178234.6 | M8: 171461.9 | N8: 175298.6 | O8: 181640.3 | P8: 0 | Q8: 0 | R8: 0 | S8: million ton-km
A9: Calib_TRN_SW_PassKm_L4,date=2025-29-4T16:10:05+02:00 | B9: EU-12 | C9: trn_freight | D9: road | E9: 263310 | F9: 397360 | G9: 479298 | H9: 494165 | I9: 545559 | J9: 614550 | K9: 689248 | L9: 758717 | M9: 810007 | N9: 842771 | O9: 867036 | P9: 0 | Q9: 0 | R9: 0 | S9: million ton-km
A10: Calib_TRN_SW_PassKm_L4,date=2025-29-4T16:10:05+02:00 | B10: EU-12 | C10: trn_freight_road | D10: Heavy truck | E10: 233530 | F10: 354422 | G10: 427651 | H10: 440708 | I10: 486592.3 | J10: 547743.78 | K10: 613777.26 | L10: 675406.31 | M10: 721078.49 | N10: 749996.44 | O10: 770801.15 | P10: 0 | Q10: 0 | R10: 0 | S10: million ton-km
A11: Calib_TRN_SW_PassKm_L4,date=2025-29-4T16:10:05+02:00 | B11: EU-12 | C11: trn_freight_road | D11: Light truck | E11: 6938.53 | F11: 8895.31 | G11: 10510.8 | H11: 10995.6 | I11: 12126.824 | J11: 13724.69 | K11: 15476.343 | L11: 17085.937 | M11: 18238.611 | N11: 18970.201 | O11: 19542.285 | P11: 0 | Q11: 0 | R11: 0 | S11: million ton-km
A12: Calib_TRN_SW_PassKm_L4,date=2025-29-4T16:10:05+02:00 | B12: EU-12 | C12: trn_freight_road | D12: Medium truck | E12: 22841.6 | F12: 34042.9 | G12: 41136.2 | H12: 42461.6 | I12: 46840.1 | J12: 53084.599 | K12: 60005.408 | L12: 66244.236 | M12: 70720.087 | N12: 73838.717 | O12: 76733.442 | P12: 0 | Q12: 0 | R12: 0 | S12: million ton-km
A13: Calib_TRN_SW_PassKm_L4,date=2025-29-4T16:10:05+02:00 | B13: EU-12 | C13: trn_pass | D13: Cycle | E13: 17265.8 | F13: 16531.9 | G13: 16277.9 | H13: 16023.9 | I13: 14530.5 | J13: 17633.6 | K13: 19646.3 | L13: 21256.8 | M13: 22765 | N13: 24068.1 | O13: 25173.3 | P13: 0 | Q13: 0 | R13: 0 | S13: million pass-km
A14: Calib_TRN_SW_PassKm_L4,date=2025-29-4T16:10:05+02:00 | B14: EU-12 | C14: trn_pass | D14: Domestic Aviation | E14: 5331.03 | F14: 5193.26 | G14: 5821.69 | H14: 6241.59 | I14: 7625.92 | J14: 8780.91 | K14: 8657.99 | L14: 7076.2335 | M14: 4989.4833 | N14: 2556.6157 | O14: 0 | P14: 0 | Q14: 0 | R14: 0 | S14: million pass-km
A15: Calib_TRN_SW_PassKm_L4,date=2025-29-4T16:10:05+02:00 | B15: EU-12 | C15: trn_pass | D15: HSR | E15: 0 | F15: 0 | G15: 0 | H15: 0 | I15: 327.275 | J15: 434.901 | K15: 533.245 | L15: 627.467 | M15: 720.683 | N15: 818.32 | O15: 922.421 | P15: 0 | Q15: 0 | R15: 0 | S15: million pass-km
A16: Calib_TRN_SW_PassKm_L4,date=2025-29-4T16:10:05+02:00 | B16: EU-12 | C16: trn_pass | D16: Passenger Rail | E16: 88848.87 | F16: 70151.4 | G16: 61930.3 | H16: 57839.1 | I16: 60895 | J16: 66567.2 | K16: 69288 | L16: 71116.6 | M16: 72137.3 | N16: 73040.6 | O16: 73855.1 | P16: 0 | Q16: 0 | R16: 0 | S16: million pass-km
... A45: Calib_TRN_SW_PassKm_L4,date=2025-29-4T16:10:05+02:00 | B45: EU-15 | C45: trn_shipping_intl | D45: International Ship | E45: 12346400 | F45: 18282500 | G45: 16574700 | H45: 14015900 | I45: 14055326 | J45: 14863190 | K45: 15443890 | L45: 16476190 | M45: 17196033 | N45: 17769063 | O45: 18336934 | P45: 0 | Q45: 0 | R45: 0 | S45: million ton-km
A47: income.elasticity
A48: region | B48: energy.final.demand | C48: 2020 | D48: 2025 | E48: 2030 | F48: 2035 | G48: 2040 | H48: 2045 | I48: 2050
A49: EU-12 | B49: trn_pass | C49: 1 | D49: 1 | E49: 1 | F49: 1 | G49: 1 | H49: 1 | I49: 1
A50: EU-12 | B50: trn_freight | C50: 0.75 | D50: 0.75 | E50: 0.75 | F50: 0.75 | G50: 0.75 | H50: 0.75 | I50: 0.75
A51: EU-12 | B51: trn_aviation_intl | C51: 1 | D51: 0.13131756 | E51: 0.13131756 | F51: 0.13131756 | G51: 0.13131756 | H51: 0.13131756 | I51: 0.13131756
A52: EU-12 | B52: trn_shipping_intl | C52: 0.4 | D52: 0.4 | E52: 0.4 | F52: 0.4 | G52: 0.4 | H52: 0.4 | I52: 0.4
A53: EU-15 | B53: trn_pass | C53: 1 | D53: 1 | E53: 1 | F53: 1 | G53: 1 | H53: 1 | I53: 1
A54: EU-15 | B54: trn_freight | C54: 0.75 | D54: 0.75 | E54: 0.75 | F54: 0.75 | G54: 0.75 | H54: 0.75 | I54: 0.75
A55: EU-15 | B55: trn_aviation_intl | C55: 1 | D55: -1.5077826 | E55: -1.5077826 | F55: -1.5077826 | G55: -1.5077826 | H55: -1.5077826 | I55: -1.5077826
A56: EU-15 | B56: trn_shipping_intl | C56: 0.4 | D56: 0.4 | E56: 0.4 | F56: 0.4 | G56: 0.4 | H56: 0.4 | I56: 0.4
A58: GOAL data
A59: mode | B59: GCAM_region_ID | C59: 2015 | D59: 2020 | E59: 2050 | F59: Unit
A60: DomAv | B60: 12 | C60: 2468.3278 | D60: 3893.7574 | E60: 0 | F60: pass million km/year
A61: DomAv | B61: 13 | C61: 82393.468 | D61: 84187.599 | E61: 18070.288 | F61: pass million km/year
A62: IntAv | B62: 12 | C62: 77602.589 | D62: 77506.716 | E62: 128866.04 | F62: pass million km/year
A63: IntAv | B63: 13 | C63: 928364.54 | D63: 928899.23 | E63: 496684.54 | F63: pass million km/year
A64: Pass - noAv - noNMT | B64: 12 | C64: 826410.93 | D64: 890626.88 | E64: 1124625.9 | F64: pass million km/year
A65: Pass - noAv - noNMT | B65: 13 | C65: 4253237.3 | D65: 4483839.2 | E65: 3974912.3 | F65: pass million km/year
A66: TOTAL pass | B66: 12 | C66: =C60+C64 -> 828879.26 | D66: =D60+D64 -> 894520.64 | E66: =E60+E64 -> 1124625.9 | F66: pass million km/year
A67: TOTAL pass | B67: 13 | C67: =C61+C65 -> 4335630.8 | D67: =D61+D65 -> 4568026.8 | E67: =E61+E65 -> 3992982.6 | F67: pass million km/year
A69: 2. COMPUTATION Pass km - income elasticity
A70: GCAM data | B70: 2015 | C70: 2020 | D70: 2050 | E70: porcentual change with respect 2015 | G70: Factor computation | J70: 2015 | K70: 2020 | L70: 2025 | M70: 2030 | N70: 2035 | O70: 2040 | P70: 2045 | Q70: 2050
A71: Service Output | E71: GCAM data | F71: GOAL data | G71: Target diff | H71: Target diff accounting for GDP | I71: Income Elasticity
A72: EU-12 | F72: NOTE: HALF percentage | I72: EU-12
...

Sheet TRN-PassKM-values
A1: region | B1: mode | C1: {='TRN-PassKM-computation'!J70:Q70} -> 2015 | D1: 2020 | E1: 2025 | F1: 2030 | G1: 2035 | H1: 2040 | I1: 2045 | J1: 2050 | K1: energy.final.demand
A2: EU-12 | B2: {='TRN-PassKM-computation'!I76:Q76} -> Total pass | C2: 1 | D2: 1 | E2: 1.22 | F2: 1.22 | G2: 1.22 | H2: 1.22 | I2: 1.22 | J2: 1.22 | K2: trn_pass
A3: EU-15 | B3: {='TRN-PassKM-computation'!I82:Q82} -> Total pass | C3: 1 | D3: 1 | E3: 1.13 | F3: 1.13 | G3: 1.13 | H3: 1.13 | I3: 1.13 | J3: 1.13 | K3: trn_pass

Sheet TRN-CHECK
A1: CHECK
A3: 1. Data from GCAM (LoadFactor Hscen)
A4: transport service output by mode
A5: scenario | B5: region | C5: sector | D5: mode | E5: 1990 | F5: 2005 | G5: 2010 | H5: 2015 | I5: 2020 | J5: 2025 | K5: 2030 | L5: 2035 | M5: 2040 | N5: 2045 | O5: 2050 | P5: 2065 | Q5: 2080 | R5: 2095 | S5: Units
A6: Calib_TRN_SW_PassKm_L6,date=2025-30-4T11:05:45+02:00 | B6: EU-12 | C6: trn_aviation_intl | D6: International Aviation | E6: 32280.9 | F6: 34737.6 | G6: 41232.1 | H6: 44763.7 | I6: 51257.6 | J6: 54351 | K6: 54459.5 | L6: 52515.23 | M6: 50584.693 | N6: 48862.951 | O6: 47367.312 | P6: 0 | Q6: 0 | R6: 0 | S6: million pass-km
A7: Calib_TRN_SW_PassKm_L6,date=2025-30-4T11:05:45+02:00 | B7: EU-12 | C7: trn_freight | D7: Domestic Ship | E7: 70700.7 | F7: 13111.1 | G7: 17363.7 | H7: 15470.5 | I7: 18041.241 | J7: 21689.36 | K7: 26558 | L7: 32830.506 | M7: 36525.109 | N7: 38456.112 | O7: 39927.394 | P7: 0 | Q7: 0 | R7: 0 | S7: million ton-km
A8: Calib_TRN_SW_PassKm_L6,date=2025-30-4T11:05:45+02:00 | B8: EU-12 | C8: trn_freight | D8: Freight Rail | E8: 262042.36 | F8: 198205.21 | G8: 175160.2 | H8: 164781.04 | I8: 183270.9 | J8: 203212.93 | K8: 200123.8 | L8: 178271.1 | M8: 171502.3 | N8: 175332.7 | O8: 181666.7 | P8: 0 | Q8: 0 | R8: 0 | S8: million ton-km
A9: Calib_TRN_SW_PassKm_L6,date=2025-30-4T11:05:45+02:00 | B9: EU-12 | C9: trn_freight | D9: road | E9: 263310 | F9: 397360 | G9: 479298 | H9: 494165 | I9: 545559 | J9: 614501 | K9: 689142 | L9: 758575 | M9: 809834 | N9: 842620 | O9: 866909 | P9: 0 | Q9: 0 | R9: 0 | S9: million ton-km
A10: Calib_TRN_SW_PassKm_L6,date=2025-30-4T11:05:45+02:00 | B10: EU-12 | C10: trn_freight_road | D10: Heavy truck | E10: 233530 | F10: 354422 | G10: 427651 | H10: 440708 | I10: 486592.3 | J10: 547699.88 | K10: 613677.61 | L10: 675272.73 | M10: 720913.21 | N10: 749851.47 | O10: 770677.61 | P10: 0 | Q10: 0 | R10: 0 | S10: million ton-km
A11: Calib_TRN_SW_PassKm_L6,date=2025-30-4T11:05:45+02:00 | B11: EU-12 | C11: trn_freight_road | D11: Light truck | E11: 6938.53 | F11: 8895.31 | G11: 10510.8 | H11: 10995.6 | I11: 12126.824 | J11: 13723.918 | K11: 15475.033 | L11: 17085.022 | M11: 18237.84 | N11: 18970.31 | O11: 19542.803 | P11: 0 | Q11: 0 | R11: 0 | S11: million ton-km
A12: Calib_TRN_SW_PassKm_L6,date=2025-30-4T11:05:45+02:00 | B12: EU-12 | C12: trn_freight_road | D12: Medium truck | E12: 22841.6 | F12: 34042.9 | G12: 41136.2 | H12: 42461.6 | I12: 46840.1 | J12: 53081.259 | K12: 59998.79 | L12: 66237.685 | M12: 70713.437 | N12: 73835.338 | O12: 76732.349 | P12: 0 | Q12: 0 | R12: 0 | S12: million ton-km
A13: Calib_TRN_SW_PassKm_L6,date=2025-30-4T11:05:45+02:00 | B13: EU-12 | C13: trn_pass | D13: Cycle | E13: 17265.8 | F13: 16531.9 | G13: 16277.9 | H13: 16023.9 | I13: 14530.5 | J13: 18177.7 | K13: 20802.5 | L13: 22976.3 | M13: 25016.2 | N13: 26783.9 | O13: 28311.1 | P13: 0 | Q13: 0 | R13: 0 | S13: million pass-km
A14: Calib_TRN_SW_PassKm_L6,date=2025-30-4T11:05:45+02:00 | B14: EU-12 | C14: trn_pass | D14: Domestic Aviation | E14: 5331.03 | F14: 5193.26 | G14: 5821.69 | H14: 6241.59 | I14: 7625.92 | J14: 9050.08 | K14: 9164.2 | L14: 7645.423 | M14: 5480.2413 | N14: 2843.9648 | O14: 0 | P14: 0 | Q14: 0 | R14: 0 | S14: million pass-km
A15: Calib_TRN_SW_PassKm_L6,date=2025-30-4T11:05:45+02:00 | B15: EU-12 | C15: trn_pass | D15: HSR | E15: 0 | F15: 0 | G15: 0 | H15: 0 | I15: 327.275 | J15: 448.318 | K15: 564.616 | L15: 678.204 | M15: 791.918 | N15: 910.621 | O15: 1037.35 | P15: 0 | Q15: 0 | R15: 0 | S15: million pass-km
A16: Calib_TRN_SW_PassKm_L6,date=2025-30-4T11:05:45+02:00 | B16: EU-12 | C16: trn_pass | D16: Passenger Rail | E16: 88848.87 | F16: 70151.4 | G16: 61930.3 | H16: 57839.1 | I16: 60895 | J16: 68620.1 | K16: 73363.2 | L16: 76866.1 | M16: 79267 | N16: 81278.9 | O16: 83057.8 | P16: 0 | Q16: 0 | R16: 0 | S16: million pass-km
... A45: Calib_TRN_SW_PassKm_L6,date=2025-30-4T11:05:45+02:00 | B45: EU-15 | C45: trn_shipping_intl | D45: International Ship | E45: 12346400 | F45: 18282500 | G45: 16574700 | H45: 14015900 | I45: 14055326 | J45: 14861890 | K45: 15441120 | L45: 16473214 | M45: 17193023 | N45: 17765846 | O45: 18334758 | P45: 0 | Q45: 0 | R45: 0 | S45: million ton-km
A47: transport subsector share-weights
A48: scenario | B48: region | C48: sector | D48: subsector | E48: 1990 | F48: 2005 | G48: 2010 | H48: 2015 | I48: 2020 | J48: 2025 | K48: 2030 | L48: 2035 | M48: 2040 | N48: 2045 | O48: 2050 | P48: 2055 | Q48: 2060 | R48: 2065 | S48: 2070 | T48: 2075 | U48: 2080 | V48: 2085 | W48: 2090 | X48: 2095 | Y48: 2100 | Z48: Units
A49: Calib_TRN_Modes_IntAvANDsw,date=2025-25-4T09:02:15+02:00 | B49: EU-12 | C49: trn_aviation_intl | D49: International Aviation | E49: 1 | F49: 1 | G49: 1 | H49: 1 | I49: 1 | J49: 1 | K49: 1 | L49: 1 | M49: 1 | N49: 1 | O49: 1 | P49: 1 | Q49: 1 | R49: 1 | S49: 1 | T49: 1 | U49: 1 | V49: 1 | W49: 1 | X49: 1 | Y49: 1 | Z49: none
A50: Calib_TRN_Modes_IntAvANDsw,date=2025-25-4T09:02:15+02:00 | B50: EU-12 | C50: trn_freight | D50: Domestic Ship | E50: 0.000795575 | F50: 0.000114108 | G50: 0.000240711 | H50: 0.000229626 | I50: 0.000229626 | J50: 0.000229626 | K50: 0.000229626 | L50: 0.000229626 | M50: 0.000229626 | N50: 0.000229626 | O50: 0.000229626 | P50: 0.000229626 | Q50: 0.000229626 | R50: 0.000229626 | S50: 0.000229626 | T50: 0.000229626 | U50: 0.000229626 | V50: 0.000229626 | W50: 0.000229626 | X50: 0.000229626 | Y50: 0.000229626 | Z50: none
A51: Calib_TRN_Modes_IntAvANDsw,date=2025-25-4T09:02:15+02:00 | B51: EU-12 | C51: trn_freight | D51: Freight Rail | E51: 0.201544 | F51: 0.110995 | G51: 0.0710973 | H51: 0.062487 | I51: 0.062487 | J51: 0.062487 | K51: 0.062487 | L51: 0.062487 | M51: 0.062487 | N51: 0.062487 | O51: 0.062487 | P51: 0.062487 | Q51: 0.062487 | R51: 0.062487 | S51: 0.062487 | T51: 0.062487 | U51: 0.062487 | V51: 0.062487 | W51: 0.062487 | X51: 0.062487 | Y51: 0.062487 | Z51: none
A52: Calib_TRN_Modes_IntAvANDsw,date=2025-25-4T09:02:15+02:00 | B52: EU-12 | C52: trn_freight | D52: road | E52: 1 | F52: 1 | G52: 1 | H52: 1 | I52: 1 | J52: 1 | K52: 1 | L52: 1 | M52: 1 | N52: 1 | O52: 1 | P52: 1 | Q52: 1 | R52: 1 | S52: 1 | T52: 1 | U52: 1 | V52: 1 | W52: 1 | X52: 1 | Y52: 1 | Z52: none
A53: Calib_TRN_Modes_IntAvANDsw,date=2025-25-4T09:02:15+02:00 | B53: EU-12 | C53: trn_freight_road | D53: Heavy truck | E53: 1 | F53: 1 | G53: 1 | H53: 1 | I53: 1 | J53: 1 | K53: 1 | L53: 1 | M53: 1 | N53: 1 | O53: 1 | P53: 1 | Q53: 1 | R53: 1 | S53: 1 | T53: 1 | U53: 1 | V53: 1 | W53: 1 | X53: 1 | Y53: 1 | Z53: none
A54: Calib_TRN_Modes_IntAvANDsw,date=2025-25-4T09:02:15+02:00 | B54: EU-12 | C54: trn_freight_road | D54: Light truck | E54: 0.388042 | F54: 0.326507 | G54: 0.295752 | H54: 0.295565 | I54: 0.295565 | J54: 0.295565 | K54: 0.295565 | L54: 0.295565 | M54: 0.295565 | N54: 0.295565 | O54: 0.295565 | P54: 0.295565 | Q54: 0.295565 | R54: 0.295565 | S54: 0.295565 | T54: 0.295565 | U54: 0.295565 | V54: 0.295565 | W54: 0.295565 | X54: 0.295565 | Y54: 0.295565 | Z54: none
A55: Calib_TRN_Modes_IntAvANDsw,date=2025-25-4T09:02:15+02:00 | B55: EU-12 | C55: trn_freight_road | D55: Medium truck | E55: 0.499758 | F55: 0.488309 | G55: 0.461901 | H55: 0.457693 | I55: 0.457693 | J55: 0.457693 | K55: 0.457693 | L55: 0.457693 | M55: 0.457693 | N55: 0.457693 | O55: 0.457693 | P55: 0.457693 | Q55: 0.457693 | R55: 0.457693 | S55: 0.457693 | T55: 0.457693 | U55: 0.457693 | V55: 0.457693 | W55: 0.457693 | X55: 0.457693 | Y55: 0.457693 | Z55: none
A56: Calib_TRN_Modes_IntAvANDsw,date=2025-25-4T09:02:15+02:00 | B56: EU-12 | C56: trn_pass | D56: Cycle | E56: 0.0150988 | F56: 0.0140179 | G56: 0.0128294 | H56: 0.0137751 | I56: 0.0137751 | J56: 0.0194979 | K56: 0.0252206 | L56: 0.0309434 | M56: 0.0366661 | N56: 0.0423889 | O56: 0.0481116 | P56: 1 | Q56: 1 | R56: 1 | S56: 1 | T56: 1 | U56: 1 | V56: 1 | W56: 1 | X56: 1 | Y56: 1 | Z56: none
A57: Calib_TRN_Modes_IntAvANDsw,date=2025-25-4T09:02:15+02:00 | B57: EU-12 | C57: trn_pass | D57: Domestic Aviation | E57: 0.00257035 | F57: 0.00157745 | G57: 0.0015847 | H57: 0.00149513 | I57: 0.00149513 | J57: 0.00124594 | K57: 0.000996753 | L57: 0.000747565 | M57: 0.000498377 | N57: 0.000249188 | O57: 0 | P57: 1 | Q57: 1 | R57: 1 | S57: 1 | T57: 1 | U57: 1 | V57: 1 | W57: 1 | X57: 1 | Y57: 1 | Z57: none
A58: Calib_TRN_Modes_IntAvANDsw,date=2025-25-4T09:02:15+02:00 | B58: EU-12 | C58: trn_pass | D58: HSR | E58: 0 | F58: 0 | G58: 0 | H58: 0 | I58: 5.88235e-05 | J58: 7.0399e-05 | K58: 8.19745e-05 | L58: 9.355e-05 | M58: 0.000105126 | N58: 0.000116701 | O58: 0.000128277 | P58: 0.001 | Q58: 0.001 | R58: 0.001 | S58: 0.001 | T58: 0.001 | U58: 0.001 | V58: 0.001 | W58: 0.001 | X58: 0.001 | Y58: 0.001 | Z58: none
A59: Calib_TRN_Modes_IntAvANDsw,date=2025-25-4T09:02:15+02:00 | B59: EU-12 | C59: trn_pass | D59: Passenger Rail | E59: 0.0353507 | F59: 0.020358 | G59: 0.0147021 | H59: 0.0132408 | I59: 0.0132408 | J59: 0.0158464 | K59: 0.0184519 | L59: 0.0210575 | M59: 0.0236631 | N59: 0.0262687 | O59: 0.0288742 | P59: 1 | Q59: 1 | R59: 1 | S59: 1 | T59: 1 | U59: 1 | V59: 1 | W59: 1 | X59: 1 | Y59: 1 | Z59: none
... A88: Calib_TRN_Modes_IntAvANDsw,date=2025-25-4T09:02:15+02:00 | B88: EU-15 | C88: trn_shipping_intl | D88: International Ship | E88: 1 | F88: 1 | G88: 1 | H88: 1 | I88: 1 | J88: 1 | K88: 1 | L88: 1 | M88: 1 | N88: 1 | O88: 1 | P88: 1 | Q88: 1 | R88: 1 | S88: 1 | T88: 1 | U88: 1 | V88: 1 | W88: 1 | X88: 1 | Y88: 1 | Z88: none
A92: 2. GOAL DATA
A93: GCAM_region_ID | B93: mode | C93: 2015 | D93: 2020 | E93: 2050 | F93: unit | H93: mode | I93: GCAM_region_ID | J93: 2015 | K93: 2020 | L93: 2050 | M93: Unit
A94: 12 | B94: NMT | C94: 0.071471429 | D94: 0.072092857 | E94: 0.07085 | F94: perc | H94: international aviation | I94: 12 | J94: 26465.103 | K94: 25082.175 | L94: 30046.097 | M94: pass km/year
A95: 12 | B95: domestic aviation | C95: 0.0022428571 | D95: 0.0031 | E95: 0 | F95: perc | H95: international aviation | I95: 13 | J95: 50618.2 | K95: 48798.193 | L95: 20356.115 | M95: pass km/year
A96: 12 | B96: international aviation | C96: 0.13205714 | D96: 0.12391429 | E96: 0.14175714 | F96: perc | H96: total | I96: 12 | J96: 145263.64 | K96: 155496.28 | L96: 181455.61 | M96: pass km/year
A97: 12 | B97: road (bus + LDV) | C97: 0.74164286 | D97: 0.75114286 | E97: 0.69492143 | F97: perc | H97: total | I97: 13 | J97: 229105.25 | K97: 231963.82 | L97: 183841.65 | M97: pass km/year
A98: 12 | B98: trains | C98: 0.05255 | D98: 0.04975 | E98: 0.092471429 | F98: perc
A99: 13 | B99: NMT | C99: 0.047592857 | D99: 0.047857143 | E99: 0.087585714 | F99: perc | H99: porcentual change with respect 2015
A100: 13 | B100: domestic aviation | C100: 0.0121 | D100: 0.01165 | E100: 0.0039591214 | F100: perc | H100: int av | I100: 12 | L100: =(L94-J94)/J94*0.5 -> 0.067655031
A101: 13 | B101: international aviation | C101: 0.20178571 | D101: 0.19475 | E101: 0.10266429 | F101: perc | H101: int av | I101: 13 | L101: =(L95-J95)/J95*0.5 -> -0.29892494
...

Sheet BLD-FloorSpace-computation
A1: FLOORSPACE COMPUTATION
A3: 1. Data from GCAM
A4: building floorspace
A5: scenario | B5: region | C5: nodeInput | D5: building-node-input | E5: building | F5: 1990 | G5: 2005 | H5: 2010 | I5: 2015 | J5: 2020 | K5: 2025 | L5: 2030 | M5: 2035 | N5: 2040 | O5: 2045 | P5: 2050 | Q5: Units
A6: Calib_TRN_Modes_ONLYIntAv,date=2025-24-4T15:48:40+02:00 | B6: EU-12 | C6: comm | D6: comm_building | E6: comm | F6: 0.755048 | G6: 0.822556 | H6: 0.812976 | I6: 0.802791 | J6: 0.890853 | K6: 1.01737 | L6: 1.1141 | M6: 1.18059 | N6: 1.22654 | O6: 1.25468 | P6: 1.27387 | Q6: billion m^2
A7: Calib_TRN_Modes_ONLYIntAv,date=2025-24-4T15:48:40+02:00 | B7: EU-12 | C7: resid | D7: resid_building | E7: resid | F7: 2.60838 | G7: 2.90616 | H7: 2.70237 | I7: 2.49859 | J7: 2.55658 | K7: 2.6507 | L7: 2.68605 | M7: 2.69482 | N7: 2.68917 | O7: 2.67231 | P7: 2.65186 | Q7: billion m^2
A8: Calib_TRN_Modes_ONLYIntAv,date=2025-24-4T15:48:40+02:00 | B8: EU-15 | C8: comm | D8: comm_building | E8: comm | F8: 5.07275 | G8: 5.697 | H8: 5.81243 | I8: 5.89485 | J8: 5.97216 | K8: 6.22157 | L8: 6.33102 | M8: 6.4319 | N8: 6.53148 | O8: 6.62624 | P8: 6.71154 | Q8: billion m^2
A9: Calib_TRN_Modes_ONLYIntAv,date=2025-24-4T15:48:40+02:00 | B9: EU-15 | C9: resid | D9: resid_building | E9: resid | F9: 9.91734 | G9: 11.692 | H9: 10.7706 | I9: 9.84928 | J9: 9.96452 | K9: 10.2663 | L9: 10.4005 | M9: 10.531 | N9: 10.6676 | O9: 10.8036 | P9: 10.933 | Q9: billion m^2
A13: 2. Data to be applied
A14: ctry | B14: region | C14: year | D14: m2/person | E14: thous person | F14: bnm2 | G14: m2/ctry | H14: bnm2/ctry
A15: Bulgaria | B15: EU-12 | C15: 2015 | D15: 31.005212 | E15: 7199.741 | F15: 0.00022322949 | G15: =D15*E15 * 1000 -> 2.2322949e+08 | H15: =G15/1000000000 -> 0.22322949
A16: Croatia | B16: EU-12 | C16: 2015 | D16: 30.199092 | E16: 4232.874 | F16: 0.00012782895 | G16: =D16*E16 * 1000 -> 1.2782895e+08 | H16: =G16/1000000000 -> 0.12782895
A17: Cyprus | B17: EU-12 | C17: 2015 | D17: 61.968464 | E17: 1160.985 | F17: 7.1944457e-05 | G17: =D17*E17 * 1000 -> 71944457 | H17: =G17/1000000000 -> 0.071944457
A18: Czech Republic | B18: EU-12 | C18: 2015 | D18: 32.404491 | E18: 10601.397 | F18: 0.00034353288 | G18: =D18*E18 * 1000 -> 3.4353288e+08 | H18: =G18/1000000000 -> 0.34353288
A19: Estonia | B19: EU-12 | C19: 2015 | D19: 30.561127 | E19: 1315.325 | F19: 4.0197814e-05 | G19: =D19*E19 * 1000 -> 40197814 | H19: =G19/1000000000 -> 0.040197814
A20: Hungary | B20: EU-12 | C20: 2015 | D20: 31.495982 | E20: 9777.923 | F20: 0.00030796529 | G20: =D20*E20 * 1000 -> 3.0796529e+08 | H20: =G20/1000000000 -> 0.30796529
A21: Latvia | B21: EU-12 | C21: 2015 | D21: 27.677886 | E21: 1997.674 | F21: 5.5291392e-05 | G21: =D21*E21 * 1000 -> 55291392 | H21: =G21/1000000000 -> 0.055291392
A22: Lithuania | B22: EU-12 | C22: 2015 | D22: 32.672384 | E22: 2931.88 | F22: 9.579151e-05 | G22: =D22*E22 * 1000 -> 95791510 | H22: =G22/1000000000 -> 0.09579151
A23: Malta | B23: EU-12 | C23: 2015 | D23: 40 | E23: 433.559 | F23: 1.734236e-05 | G23: =D23*E23 * 1000 -> 17342360 | H23: =G23/1000000000 -> 0.01734236
A24: Poland | B24: EU-12 | C24: 2015 | D24: 25.720708 | E24: 38034.079 | F24: 0.00097826344 | G24: =D24*E24 * 1000 -> 9.7826344e+08 | H24: =G24/1000000000 -> 0.97826344
A25: Romania | B25: EU-12 | C25: 2015 | D25: 21.129637 | E25: 19925.175 | F25: 0.00042101172 | G25: =D25*E25 * 1000 -> 4.2101172e+08 | H25: =G25/1000000000 -> 0.42101172
A26: Slovakia | B26: EU-12 | C26: 2015 | D26: 27.776876 | E26: 5435.611 | F26: 0.00015098429 | G26: =D26*E26 * 1000 -> 1.5098429e+08 | H26: =G26/1000000000 -> 0.15098429
... A95: Sweden | B95: EU-15 | C95: 2050 | D95: 47.443469 | E95: 11663.136 | F95: 0.00055333962 | G95: =D95*E95 * 1000 -> 5.5333962e+08 | H95: =G95/1000000000 -> 0.55333962
A98: 3. COMPUTATION: Total values by GCAM region - Data to be applied
A99: GCAM_region_name | C99: 2015 | D99: 2020 | E99: 2050 | F99: Unit
A100: EU-12 | C100: =SUM(H15:H27) -> 2.8970205 | D100: =SUM(H42:H54) -> 3.0570522 | E100: =SUM(H69:H81) -> 3.714843 | F100: bn m2
A101: EU-15 | C101: =SUM(H28:H41) -> 14.593662 | D101: =SUM(H55:H67) -> 14.339359 | E101: =SUM(H82:H95) -> 14.712753 | F101: bn m2
A104: 4. COMPUTATION: New floorspace values
A105: GCAM data | B105: 2015 | C105: 2020 | D105: 2050 | E105: porcentual change with respect 2015 | G105: Factor computation | I105: New Floorspace computation | N105: 0 | O105: 1 | P105: 2 | Q105: 3 | R105: 4 | S105: 5 | T105: 6 | V105: check
A106: Floorspace bnm2/ctry | E106: GCAM data | F106: GOAL data - HALF change | G106: Target diff | I106: bnm2/ctry | J106: {=F5:P5} -> 1990 | K106: 2005 | L106: 2010 | M106: 2015 | N106: 2020 | O106: 2025 | P106: 2030 | Q106: 2035 | R106: 2040 | S106: 2045 | T106: 2050 | U106: =Q5 -> Units
A107: EU-12 | B107: =I7 -> 2.49859 | C107: =J7 -> 2.55658 | D107: =P7 -> 2.65186 | E107: =(D107-B107)/B107 -> 0.061342597 | F107: =(E100-C100)/C100*0.5 -> 0.1411489 | G107: =P7 -> 2.65186 | H107: NOTE: keep ct since the base floorspace is lower than the "expected" one | I107: EU-12 | J107: {=F7:J7} -> 2.60838 | K107: 2.90616 | L107: 2.70237 | M107: 2.49859 | N107: 2.55658 | O107: =$N$107+$N$107*(($G$107-$N$107)/$N$107)*O105/$T$105 -> 2.57246 | P107: =$N$107+$N$107*(($G$107-$N$107)/$N$107)*P105/$T$105 -> 2.58834 | Q107: =$N$107+$N$107*(($G$107-$N$107)/$N$107)*Q105/$T$105 -> 2.60422 | R107: =$N$107+$N$107*(($G$107-$N$107)/$N$107)*R105/$T$105 -> 2.6201 | S107: =$N$107+$N$107*(($G$107-$N$107)/$N$107)*S105/$T$105 -> 2.63598 | T107: =$N$107+$N$107*(($G$107-$N$107)/$N$107)*T105/$T$105 -> 2.65186 | U107: {=Q6:Q7} -> billion m^2 | V107: =T107/N107 -> 1.0372685
A108: EU-15 | B108: =I9 -> 9.84928 | C108: =J9 -> 9.96452 | D108: =P9 -> 10.933 | E108: =(D108-B108)/B108 -> 0.11003038 | F108: =(E101-C101)/C101*0.5 -> 0.0040802312 | G108: =B108*(1+F108) -> 9.8894673 | I108: EU-15 | J108: {=F9:J9} -> 9.91734 | K108: 11.692 | L108: 10.7706 | M108: 9.84928 | N108: 9.96452 | O108: =$N$108+$N$108*(($G$108-$N$108)/$N$108)*O105/$T$105 -> 9.9520112 | P108: =$N$108+$N$108*(($G$108-$N$108)/$N$108)*P105/$T$105 -> 9.9395024 | Q108: =$N$108+$N$108*(($G$108-$N$108)/$N$108)*Q105/$T$105 -> 9.9269937 | R108: =$N$108+$N$108*(($G$108-$N$108)/$N$108)*R105/$T$105 -> 9.9144849 | S108: =$N$108+$N$108*(($G$108-$N$108)/$N$108)*S105/$T$105 -> 9.9019761 | T108: =$N$108+$N$108*(($G$108-$N$108)/$N$108)*T105/$T$105 -> 9.8894673 | U108: billion m^2 | V108: =T108/N108 -> 0.99246801

Sheet BLD-FloorSpace-values
A1: region | B1: {='BLD-FloorSpace-computation'!J106:T108} -> 1990 | C1: 2005 | D1: 2010 | E1: 2015 | F1: 2020 | G1: 2025 | H1: 2030 | I1: 2035 | J1: 2040 | K1: 2045 | L1: 2050
A2: EU-12 | B2: 2.60838 | C2: 2.90616 | D2: 2.70237 | E2: 2.49859 | F2: 2.55658 | G2: 2.57246 | H2: 2.58834 | I2: 2.60422 | J2: 2.6201 | K2: 2.63598 | L2: 2.65186
A3: EU-15 | B3: 9.91734 | C3: 11.692 | D3: 10.7706 | E3: 9.84928 | F3: 9.96452 | G3: 9.9520112 | H3: 9.9395024 | I3: 9.9269937 | J3: 9.9144849 | K3: 9.9019761 | L3: 9.8894673

Sheet BLD-EnConsumption-computation
A1: ENERGY CONSUMPTION COMPUTATION
A3: 1. Data from GCAM
A4: building total final energy by service
A5: scenario | B5: region | C5: sector | D5: 1990 | E5: 2005 | F5: 2010 | G5: 2015 | H5: 2020 | I5: 2025 | J5: 2030 | K5: 2035 | L5: 2040 | M5: 2045 | N5: 2050 | O5: 2065 | P5: 2080 | Q5: 2095 | R5: Units
A6: Calib_BLD_FloorSpace_L,date=2025-30-4T09:12:48+02:00 | B6: EU-12 | C6: comm cooling | D6: 0.0128655 | E6: 0.0281441 | F6: 0.0347417 | G6: 0.0330143 | H6: 0.0338376 | I6: 0.035735 | J6: 0.0366038 | K6: 0.0361838 | L6: 0.035043 | M6: 0.0334234 | N6: 0.031552 | O6: 0 | P6: 0 | Q6: 0 | R6: EJ
A7: Calib_BLD_FloorSpace_L,date=2025-30-4T09:12:48+02:00 | B7: EU-12 | C7: comm heating | D7: 0.5056642 | E7: 0.3516913 | F7: 0.3727631 | G7: 0.2904751 | H7: 0.32434407 | I7: 0.37674831 | J7: 0.41053186 | K7: 0.42595911 | L7: 0.42826857 | M7: 0.42191626 | N7: 0.41175053 | O7: 0 | P7: 0 | Q7: 0 | R7: EJ
A8: Calib_BLD_FloorSpace_L,date=2025-30-4T09:12:48+02:00 | B8: EU-12 | C8: comm others | D8: 0.3509733 | E8: 0.4950887 | F8: 0.5642249 | G8: 0.5042104 | H8: 0.60145588 | I8: 0.74555591 | J8: 0.87087113 | K8: 0.9592838 | L8: 1.0114948 | M8: 1.0411956 | N8: 1.0537297 | O8: 0 | P8: 0 | Q8: 0 | R8: EJ
A9: Calib_BLD_FloorSpace_L,date=2025-30-4T09:12:48+02:00 | B9: EU-12 | C9: resid cooling | D9: 0.023347 | E9: 0.0345223 | F9: 0.0366457 | G9: 0.0347737 | H9: 0.0337433 | I9: 0.0322343 | J9: 0.0307123 | K9: 0.028798 | L9: 0.0268747 | M9: 0.0249603 | N9: 0.0230888 | O9: 0 | P9: 0 | Q9: 0 | R9: EJ
