Workbook

Sheet TRN-LoadFactor-computation
A1: LOAD FACTOR COMPUTATION
A3: 1. Data to be applied
A4: Country | B4: GCAM_region_name | C4: Abreviation | D4: Vehicle occupancy rate | E4: 2015 | F4: 2020 | G4: 2025 | H4: 2030 | I4: 2035 | J4: 2040 | K4: 2045 | L4: 2050
A5: Austria | B5: EU-15 | C5: AT | D5: Average number of people per vehicle | E5: 1.54 | F5: 1.58 | G5: 1.68 | H5: 1.77 | I5: 1.87 | J5: 1.91 | K5: 1.93 | L5: 1.95
A6: Belgium | B6: EU-15 | C6: BE | D6: Average number of people per vehicle | E6: 1.16 | F6: 1.25 | G6: 1.4 | H6: 1.72 | I6: 1.82 | J6: 1.9 | K6: 1.95 | L6: 2
A7: Bulgaria | B7: EU-12 | C7: BG | D7: Average number of people per vehicle | E7: 1.54 | F7: 1.58 | G7: 1.68 | H7: 1.77 | I7: 1.87 | J7: 1.91 | K7: 1.93 | L7: 1.95
A8: Switzerland | C8: CH | D8: Average number of people per vehicle | E8: 1.54 | F8: 1.58 | G8: 1.68 | H8: 1.77 | I8: 1.87 | J8: 1.91 | K8: 1.93 | L8: 1.95
A9: Cyprus | B9: EU-12 | C9: CY | D9: Average number of people per vehicle | E9: 1.54 | F9: 1.58 | G9: 1.68 | H9: 1.77 | I9: 1.87 | J9: 1.91 | K9: 1.93 | L9: 1.95
A10: Czech Republic | B10: EU-12 | C10: CZ | D10: Average number of people per vehicle | E10: 1.54 | F10: 1.58 | G10: 1.68 | H10: 1.77 | I10: 1.87 | J10: 1.91 | K10: 1.93 | L10: 1.95
A11: Germany | B11: EU-15 | C11: DE | D11: Average number of people per vehicle | E11: 1.5 | F11: 1.58 | G11: 1.69 | H11: 1.8 | I11: 1.88 | J11: 1.91 | K11: 1.93 | L11: 1.95
A12: Denmark | B12: EU-15 | C12: DK | D12: Average number of people per vehicle | E12: 1.49 | F12: 1.5 | G12: 1.5 | H12: 1.5 | I12: 1.58 | J12: 1.65 | K12: 1.72 | L12: 1.8
A13: Estonia | B13: EU-12 | C13: EE | D13: Average number of people per vehicle | E13: 1.54 | F13: 1.58 | G13: 1.68 | H13: 1.77 | I13: 1.87 | J13: 1.91 | K13: 1.93 | L13: 1.95
A14: Greece | B14: EU-15 | C14: EL | D14: Average number of people per vehicle | E14: 2.1 | F14: 2.1 | G14: 2.1 | H14: 2.1 | I14: 2.1 | J14: 2.1 | K14: 2.1 | L14: 2.1
A15: Spain | B15: EU-15 | C15: ES | D15: Average number of people per vehicle | E15: 1.45 | F15: 1.45 | G15: 1.61 | H15: 1.72 | I15: 1.83 | J15: 1.88 | K15: 1.9 | L15: 1.9
A16: Finland | B16: EU-15 | C16: FI | D16: Average number of people per vehicle | E16: 1.54 | F16: 1.58 | G16: 1.68 | H16: 1.77 | I16: 1.87 | J16: 1.91 | K16: 1.93 | L16: 1.95
A17: France | B17: EU-15 | C17: FR | D17: Average number of people per vehicle | E17: 1.58 | F17: 1.69 | G17: 1.83 | H17: 1.94 | I17: 2.01 | J17: 2.08 | K17: 2.04 | L17: 2.03
A18: Croatia | B18: EU-12 | C18: HR | D18: Average number of people per vehicle | E18: 1.54 | F18: 1.58 | G18: 1.68 | H18: 1.77 | I18: 1.87 | J18: 1.91 | K18: 1.93 | L18: 1.95
A19: Hungary | B19: EU-12 | C19: HU | D19: Average number of people per vehicle | E19: 1.54 | F19: 1.58 | G19: 1.68 | H19: 1.77 | I19: 1.87 | J19: 1.91 | K19: 1.93 | L19: 1.95
A20: Ireland | B20: EU-15 | C20: IE | D20: Average number of people per vehicle | E20: 1.54 | F20: 1.58 | G20: 1.68 | H20: 1.77 | I20: 1.87 | J20: 1.91 | K20: 1.93 | L20: 1.95
... A26: Netherlands | B26: EU-15 | C26: NL | D26: Average number of people per vehicle | E26: 1.54 | F26: 1.58 | G26: 1.68 | H26: 1.77 | I26: 1.87 | J26: 1.91 | K26: 1.93 | L26: 1.95
A27: Norway | C27: NO | D27: Average number of people per vehicle | E27: 1.54 | F27: 1.58 | G27: 1.68 | H27: 1.77 | I27: 1.87 | J27: 1.91 | K27: 1.93 | L27: 1.95
A28: Poland | B28: EU-12 | C28: PL | D28: Average number of people per vehicle | E28: 1.54 | F28: 1.58 | G28: 1.68 | H28: 1.77 | I28: 1.87 | J28: 1.91 | K28: 1.93 | L28: 1.95
A29: Portugal | B29: EU-15 | C29: PT | D29: Average number of people per vehicle | E29: 1.54 | F29: 1.58 | G29: 1.68 | H29: 1.77 | I29: 1.87 | J29: 1.91 | K29: 1.93 | L29: 1.95
A30: Romania | B30: EU-12 | C30: RO | D30: Average number of people per vehicle | E30: 1.54 | F30: 1.58 | G30: 1.68 | H30: 1.77 | I30: 1.87 | J30: 1.91 | K30: 1.93 | L30: 1.95
A31: Sweden | B31: EU-15 | C31: SE | D31: Average number of people per vehicle | E31: 1.39 | F31: 1.41 | G31: 1.56 | H31: 1.75 | I31: 1.85 | J31: 1.9 | K31: 1.9 | L31: 1.9
A32: Slovenia | B32: EU-12 | C32: SI | D32: Average number of people per vehicle | E32: 1.54 | F32: 1.58 | G32: 1.68 | H32: 1.77 | I32: 1.87 | J32: 1.91 | K32: 1.93 | L32: 1.95
A33: Slovakia | B33: EU-12 | C33: SK | D33: Average number of people per vehicle | E33: 1.54 | F33: 1.58 | G33: 1.68 | H33: 1.77 | I33: 1.87 | J33: 1.91 | K33: 1.93 | L33: 1.95
A34: United Kingdom | C34: UK | D34: Average number of people per vehicle | E34: 1.54 | F34: 1.58 | G34: 1.68 | H34: 1.77 | I34: 1.87 | J34: 1.91 | K34: 1.93 | L34: 1.95
A37: 2. Average values by GCAM region
A38: GCAM_region_name | E38: 2015 | F38: 2020 | G38: 2025 | H38: 2030 | I38: 2035 | J38: 2040 | K38: 2045 | L38: 2050
A39: EU-12 | E39: =SUMIF($B$5:$B$34, $A$39, E5:E34)/ COUNTIF($B$5:$B$34, $A$39) -> 1.5484615 | F39: =SUMIF($B$5:$B$34, $A$39, F5:F34)/ COUNTIF($B$5:$B$34, $A$39) -> 1.5853846 | G39: =SUMIF($B$5:$B$34, $A$39, G5:G34)/ COUNTIF($B$5:$B$34, $A$39) -> 1.6823077 | H39: =SUMIF($B$5:$B$34, $A$39, H5:H34)/ COUNTIF($B$5:$B$34, $A$39) -> 1.7723077 | I39: =SUMIF($B$5:$B$34, $A$39, I5:I34)/ COUNTIF($B$5:$B$34, $A$39) -> 1.8692308 | J39: =SUMIF($B$5:$B$34, $A$39, J5:J34)/ COUNTIF($B$5:$B$34, $A$39) -> 1.9084615 | K39: =SUMIF($B$5:$B$34, $A$39, K5:K34)/ COUNTIF($B$5:$B$34, $A$39) -> 1.9276923 | L39: =SUMIF($B$5:$B$34, $A$39, L5:L34)/ COUNTIF($B$5:$B$34, $A$39) -> 1.9461538
A40: EU-15 | E40: =SUMIF($B$5:$B$34, $A$40, E6:E35)/COUNTIF($B$5:$B$34, $A$40) -> 1.5135714 | F40: =SUMIF($B$5:$B$34, $A$40, F6:F35)/COUNTIF($B$5:$B$34, $A$40) -> 1.5542857 | G40: =SUMIF($B$5:$B$34, $A$40, G6:G35)/COUNTIF($B$5:$B$34, $A$40) -> 1.655 | H40: =SUMIF($B$5:$B$34, $A$40, H6:H35)/COUNTIF($B$5:$B$34, $A$40) -> 1.7578571 | I40: =SUMIF($B$5:$B$34, $A$40, I6:I35)/COUNTIF($B$5:$B$34, $A$40) -> 1.8521429 | J40: =SUMIF($B$5:$B$34, $A$40, J6:J35)/COUNTIF($B$5:$B$34, $A$40) -> 1.8992857 | K40: =SUMIF($B$5:$B$34, $A$40, K6:K35)/COUNTIF($B$5:$B$34, $A$40) -> 1.92 | L40: =SUMIF($B$5:$B$34, $A$40, L6:L35)/COUNTIF($B$5:$B$34, $A$40) -> 1.9414286
A43: 3. Load factor change by period
A44: GCAM_region_name | E44: 2015 | F44: 2020 | G44: 2025 | H44: 2030 | I44: 2035 | J44: 2040 | K44: 2045 | L44: 2050
A45: EU-12 | E45: 1 | F45: =100*(F39-E39)/E39 -> 2.3845007 | G45: =100*(G39-F39)/F39 -> 6.1135371 | H45: =100*(H39-G39)/G39 -> 5.3497942 | I45: =100*(I39-H39)/H39 -> 5.46875 | J45: =100*(J39-I39)/I39 -> 2.0987654 | K45: =100*(K39-J39)/J39 -> 1.0076582 | L45: =100*(L39-K39)/K39 -> 0.95770152
A46: EU-15 | E46: 1 | F46: =100*(F40-E40)/E40 -> 2.6899481 | G46: =100*(G40-F40)/F40 -> 6.4797794 | H46: =100*(H40-G40)/G40 -> 6.2149331 | I46: =100*(I40-H40)/H40 -> 5.3636733 | J46: =100*(J40-I40)/I40 -> 2.5453143 | K46: =100*(K40-J40)/J40 -> 1.0906356 | L46: =100*(L40-K40)/K40 -> 1.1160714
A49: 4. Reshape
A50: region | B50: year | C50: changeRate
A51: {=INDEX($A$45:$A$46, INT((ROW()-ROW($A$50))/8)+1)} -> EU-12 | B51: {=INDEX($E$44:L$44, MOD(ROW()-ROW($B$50), 8)+1)} -> 2020 | C51: {=INDEX($E$45:$L$46, INT((ROW()-ROW($C$50))/8)+1, MOD(ROW()-ROW($C$50), 8)+1)} -> 2.3845007
A52: {=INDEX($A$45:$A$46, INT((ROW()-ROW($A$50))/8)+1)} -> EU-12 | B52: {=INDEX($E$44:L$44, MOD(ROW()-ROW($B$50), 8)+1)} -> 2025 | C52: {=INDEX($E$45:$L$46, INT((ROW()-ROW($C$50))/8)+1, MOD(ROW()-ROW($C$50), 8)+1)} -> 6.1135371
...

Sheet TRN-LoadFactor-values
A1: {='TRN-LoadFactor-computation'!A50:C65} -> region | B1: year | C1: changeRate
A2: EU-12 | B2: 2020 | C2: 2.3845007
A3: EU-12 | B3: 2025 | C3: 6.1135371
A4: EU-12 | B4: 2030 | C4: 5.3497942
A5: EU-12 | B5: 2035 | C5: 5.46875
A6: EU-12 | B6: 2040 | C6: 2.0987654
A7: EU-12 | B7: 2045 | C7: 1.0076582
A8: EU-12 | B8: 2050 | C8: 0.95770152
A9: EU-15 | B9: 2015 | C9: 1
A10: EU-15 | B10: 2020 | C10: 2.6899481
A11: EU-15 | B11: 2025 | C11: 6.4797794
A12: EU-15 | B12: 2030 | C12: 6.2149331
A13: EU-15 | B13: 2035 | C13: 5.3636733
... A16: EU-15 | B16: 2050 | C16: 1.1160714

Sheet TRN-Modes-computation
A1: MODES COMPUTATION
A3: 1. Data from GCAM (LoadFactor Hscen)
A4: transport service output by mode
A5: scenario | B5: region | C5: sector | D5: mode | E5: 1990 | F5: 2005 | G5: 2010 | H5: 2015 | I5: 2020 | J5: 2025 | K5: 2030 | L5: 2035 | M5: 2040 | N5: 2045 | O5: 2050 | P5: 2065 | Q5: 2080 | R5: 2095 | S5: Units
A6: Calib_LoadFactor2,date=2025-23-4T15:03:25+02:00 | B6: EU-12 | C6: trn_aviation_intl | D6: International Aviation | E6: 32280.9 | F6: 34737.6 | G6: 41232.1 | H6: 44763.7 | I6: 51256.8 | J6: 64214.1 | K6: 74527.6 | L6: 80476.646 | M6: 84871.663 | N6: 87862.98 | O6: 90269.441 | P6: 0 | Q6: 0 | R6: 0 | S6: million pass-km
A7: Calib_LoadFactor2,date=2025-23-4T15:03:25+02:00 | B7: EU-12 | C7: trn_freight | D7: Domestic Ship | E7: 70700.7 | F7: 13111.1 | G7: 17363.7 | H7: 15470.5 | I7: 18039.82 | J7: 21663.79 | K7: 26479.9 | L7: 32708.983 | M7: 36356.353 | N7: 38252.452 | O7: 39725.384 | P7: 0 | Q7: 0 | R7: 0 | S7: million ton-km
A8: Calib_LoadFactor2,date=2025-23-4T15:03:25+02:00 | B8: EU-12 | C8: trn_freight | D8: Freight Rail | E8: 262042.36 | F8: 198205.21 | G8: 175160.2 | H8: 164781.04 | I8: 183274.3 | J8: 203259.25 | K8: 200243.1 | L8: 178406.4 | M8: 171659.4 | N8: 175512.3 | O8: 181836.8 | P8: 0 | Q8: 0 | R8: 0 | S8: million ton-km
A9: Calib_LoadFactor2,date=2025-23-4T15:03:25+02:00 | B9: EU-12 | C9: trn_freight | D9: road | E9: 263310 | F9: 397360 | G9: 479298 | H9: 494165 | I9: 545552 | J9: 614375 | K9: 688784 | L9: 758104 | M9: 809231 | N9: 841914 | O9: 866222 | P9: 0 | Q9: 0 | R9: 0 | S9: million ton-km
A10: Calib_LoadFactor2,date=2025-23-4T15:03:25+02:00 | B10: EU-12 | C10: trn_freight_road | D10: Heavy truck | E10: 233530 | F10: 354422 | G10: 427651 | H10: 440708 | I10: 486585.21 | J10: 547583.21 | K10: 613347.86 | L10: 674826.58 | M10: 720337.52 | N10: 749169.94 | O10: 770004.83 | P10: 0 | Q10: 0 | R10: 0 | S10: million ton-km
A11: Calib_LoadFactor2,date=2025-23-4T15:03:25+02:00 | B11: EU-12 | C11: trn_freight_road | D11: Light truck | E11: 6938.53 | F11: 8895.31 | G11: 10510.8 | H11: 10995.6 | I11: 12126.703 | J11: 13721.919 | K11: 15470.392 | L11: 17081.814 | M11: 18235.023 | N11: 18968.25 | O11: 19542.919 | P11: 0 | Q11: 0 | R11: 0 | S11: million ton-km
A12: Calib_LoadFactor2,date=2025-23-4T15:03:25+02:00 | B12: EU-12 | C12: trn_freight_road | D12: Medium truck | E12: 22841.6 | F12: 34042.9 | G12: 41136.2 | H12: 42461.6 | I12: 46839.48 | J12: 53072.465 | K12: 59976.177 | L12: 66215.462 | M12: 70689.366 | N12: 73812.972 | O12: 76719.62 | P12: 0 | Q12: 0 | R12: 0 | S12: million ton-km
A13: Calib_LoadFactor2,date=2025-23-4T15:03:25+02:00 | B13: EU-12 | C13: trn_pass | D13: Cycle | E13: 17265.8 | F13: 16531.9 | G13: 16277.9 | H13: 16023.9 | I13: 14467.3 | J13: 12908.4 | K13: 11555.2 | L13: 10533.8 | M13: 9884.53 | N13: 9341.42 | O13: 8867.47 | P13: 0 | Q13: 0 | R13: 0 | S13: million pass-km
A14: Calib_LoadFactor2,date=2025-23-4T15:03:25+02:00 | B14: EU-12 | C14: trn_pass | D14: Domestic Aviation | E14: 5331.03 | F14: 5193.26 | G14: 5821.69 | H14: 6241.59 | I14: 7592.54 | J14: 10863.3 | K14: 13870.3 | L14: 15597.648 | M14: 17104.321 | N14: 18098.762 | O14: 18826.929 | P14: 0 | Q14: 0 | R14: 0 | S14: million pass-km
A15: Calib_LoadFactor2,date=2025-23-4T15:03:25+02:00 | B15: EU-12 | C15: trn_pass | D15: HSR | E15: 0 | F15: 0 | G15: 0 | H15: 0 | I15: 332.385 | J15: 872.175 | K15: 1538.51 | L15: 2331.1 | M15: 3182.59 | N15: 4189.79 | O15: 5365.01 | P15: 0 | Q15: 0 | R15: 0 | S15: million pass-km
A16: Calib_LoadFactor2,date=2025-23-4T15:03:25+02:00 | B16: EU-12 | C16: trn_pass | D16: Passenger Rail | E16: 88848.87 | F16: 70151.4 | G16: 61930.3 | H16: 57839.1 | I16: 61252.1 | J16: 65091.5 | K16: 65146.9 | L16: 64534 | M16: 63134.1 | N16: 62053.9 | O16: 61115.7 | P16: 0 | Q16: 0 | R16: 0 | S16: million pass-km
... A45: Calib_LoadFactor2,date=2025-23-4T15:03:25+02:00 | B45: EU-15 | C45: trn_shipping_intl | D45: International Ship | E45: 12346400 | F45: 18282500 | G45: 16574700 | H45: 14015900 | I45: 14055230 | J45: 14856130 | K45: 15426040 | L45: 16455167 | M45: 17170537 | N45: 17741282 | O45: 18312828 | P45: 0 | Q45: 0 | R45: 0 | S45: million ton-km
A47: income.elasticity | E47: 1990 | F47: 2005 | G47: 2010 | H47: 2015 | I47: 2020 | J47: 2025 | K47: 2030 | L47: 2035 | M47: 2040 | N47: 2045 | O47: 2050 | P47: 2065 | Q47: 2080 | R47: 2095 | S47: Units
B48: EU-12 | C48: trn_aviation_intl | D48: International Aviation | E48: 1 | F48: 1 | G48: 1 | H48: 1 | I48: 1 | J48: 1 | K48: 1 | L48: 1 | M48: 1 | N48: 1 | O48: 1 | S48: unitless
B49: EU-15 | C49: trn_aviation_intl | D49: International Aviation | E49: 1 | F49: 1 | G49: 1 | H49: 1 | I49: 1 | J49: 1 | K49: 1 | L49: 1 | M49: 1 | N49: 1 | O49: 1 | S49: unitless
A51: transport subsector share-weights
A52: scenario | B52: region | C52: sector | D52: subsector | E52: 1990 | F52: 2005 | G52: 2010 | H52: 2015 | I52: 2020 | J52: 2025 | K52: 2030 | L52: 2035 | M52: 2040 | N52: 2045 | O52: 2050 | P52: 2055 | Q52: 2060 | R52: 2065 | S52: 2070 | T52: 2075 | U52: 2080 | V52: 2085 | W52: 2090 | X52: 2095 | Y52: 2100 | Z52: Units
A53: Calib_LoadFactor,date=2025-23-4T12:31:16+02:00 | B53: EU-12 | C53: trn_aviation_intl | D53: International Aviation | E53: 1 | F53: 1 | G53: 1 | H53: 1 | I53: 1 | J53: 1 | K53: 1 | L53: 1 | M53: 1 | N53: 1 | O53: 1 | P53: 1 | Q53: 1 | R53: 1 | S53: 1 | T53: 1 | U53: 1 | V53: 1 | W53: 1 | X53: 1 | Y53: 1 | Z53: none
A54: Calib_LoadFactor,date=2025-23-4T12:31:16+02:00 | B54: EU-12 | C54: trn_freight | D54: Domestic Ship | E54: 0.000795575 | F54: 0.000114108 | G54: 0.000240711 | H54: 0.000229626 | I54: 0.000229626 | J54: 0.000229626 | K54: 0.000229626 | L54: 0.000229626 | M54: 0.000229626 | N54: 0.000229626 | O54: 0.000229626 | P54: 0.000229626 | Q54: 0.000229626 | R54: 0.000229626 | S54: 0.000229626 | T54: 0.000229626 | U54: 0.000229626 | V54: 0.000229626 | W54: 0.000229626 | X54: 0.000229626 | Y54: 0.000229626 | Z54: none
A55: Calib_LoadFactor,date=2025-23-4T12:31:16+02:00 | B55: EU-12 | C55: trn_freight | D55: Freight Rail | E55: 0.201544 | F55: 0.110995 | G55: 0.0710973 | H55: 0.062487 | I55: 0.062487 | J55: 0.062487 | K55: 0.062487 | L55: 0.062487 | M55: 0.062487 | N55: 0.062487 | O55: 0.062487 | P55: 0.062487 | Q55: 0.062487 | R55: 0.062487 | S55: 0.062487 | T55: 0.062487 | U55: 0.062487 | V55: 0.062487 | W55: 0.062487 | X55: 0.062487 | Y55: 0.062487 | Z55: none
A56: Calib_LoadFactor,date=2025-23-4T12:31:16+02:00 | B56: EU-12 | C56: trn_freight | D56: road | E56: 1 | F56: 1 | G56: 1 | H56: 1 | I56: 1 | J56: 1 | K56: 1 | L56: 1 | M56: 1 | N56: 1 | O56: 1 | P56: 1 | Q56: 1 | R56: 1 | S56: 1 | T56: 1 | U56: 1 | V56: 1 | W56: 1 | X56: 1 | Y56: 1 | Z56: none
A57: Calib_LoadFactor,date=2025-23-4T12:31:16+02:00 | B57: EU-12 | C57: trn_freight_road | D57: Heavy truck | E57: 1 | F57: 1 | G57: 1 | H57: 1 | I57: 1 | J57: 1 | K57: 1 | L57: 1 | M57: 1 | N57: 1 | O57: 1 | P57: 1 | Q57: 1 | R57: 1 | S57: 1 | T57: 1 | U57: 1 | V57: 1 | W57: 1 | X57: 1 | Y57: 1 | Z57: none
A58: Calib_LoadFactor,date=2025-23-4T12:31:16+02:00 | B58: EU-12 | C58: trn_freight_road | D58: Light truck | E58: 0.388042 | F58: 0.326507 | G58: 0.295752 | H58: 0.295565 | I58: 0.295565 | J58: 0.295565 | K58: 0.295565 | L58: 0.295565 | M58: 0.295565 | N58: 0.295565 | O58: 0.295565 | P58: 0.295565 | Q58: 0.295565 | R58: 0.295565 | S58: 0.295565 | T58: 0.295565 | U58: 0.295565 | V58: 0.295565 | W58: 0.295565 | X58: 0.295565 | Y58: 0.295565 | Z58: none
A59: Calib_LoadFactor,date=2025-23-4T12:31:16+02:00 | B59: EU-12 | C59: trn_freight_road | D59: Medium truck | E59: 0.499758 | F59: 0.488309 | G59: 0.461901 | H59: 0.457693 | I59: 0.457693 | J59: 0.457693 | K59: 0.457693 | L59: 0.457693 | M59: 0.457693 | N59: 0.457693 | O59: 0.457693 | P59: 0.457693 | Q59: 0.457693 | R59: 0.457693 | S59: 0.457693 | T59: 0.457693 | U59: 0.457693 | V59: 0.457693 | W59: 0.457693 | X59: 0.457693 | Y59: 0.457693 | Z59: none
A60: Calib_LoadFactor,date=2025-23-4T12:31:16+02:00 | B60: EU-12 | C60: trn_pass | D60: Cycle | E60: 0.0150988 | F60: 0.0140179 | G60: 0.0128294 | H60: 0.0137751 | I60: 0.0137751 | J60: 0.0137751 | K60: 0.0137751 | L60: 0.0137751 | M60: 0.0137751 | N60: 0.0137751 | O60: 0.0137751 | P60: 0.0137751 | Q60: 0.0137751 | R60: 0.0137751 | S60: 0.0137751 | T60: 0.0137751 | U60: 0.0137751 | V60: 0.0137751 | W60: 0.0137751 | X60: 0.0137751 | Y60: 0.0137751 | Z60: none
A61: Calib_LoadFactor,date=2025-23-4T12:31:16+02:00 | B61: EU-12 | C61: trn_pass | D61: Domestic Aviation | E61: 0.00257035 | F61: 0.00157745 | G61: 0.0015847 | H61: 0.00149513 | I61: 0.00149513 | J61: 0.00149513 | K61: 0.00149513 | L61: 0.00149513 | M61: 0.00149513 | N61: 0.00149513 | O61: 0.00149513 | P61: 0.00149513 | Q61: 0.00149513 | R61: 0.00149513 | S61: 0.00149513 | T61: 0.00149513 | U61: 0.00149513 | V61: 0.00149513 | W61: 0.00149513 | X61: 0.00149513 | Y61: 0.00149513 | Z61: none
A62: Calib_LoadFactor,date=2025-23-4T12:31:16+02:00 | B62: EU-12 | C62: trn_pass | D62: HSR | E62: 0 | F62: 0 | G62: 0 | H62: 0 | I62: 5.88235e-05 | J62: 0.000117647 | K62: 0.000176471 | L62: 0.000235294 | M62: 0.000294118 | N62: 0.000352941 | O62: 0.000411765 | P62: 0.000470588 | Q62: 0.000529412 | R62: 0.000588235 | S62: 0.000647059 | T62: 0.000705882 | U62: 0.000764706 | V62: 0.000823529 | W62: 0.000882353 | X62: 0.000941176 | Y62: 0.001 | Z62: none
A63: Calib_LoadFactor,date=2025-23-4T12:31:16+02:00 | B63: EU-12 | C63: trn_pass | D63: Passenger Rail | E63: 0.0353507 | F63: 0.020358 | G63: 0.0147021 | H63: 0.0132408 | I63: 0.0132408 | J63: 0.0132408 | K63: 0.0132408 | L63: 0.0132408 | M63: 0.0132408 | N63: 0.0132408 | O63: 0.0132408 | P63: 0.0132408 | Q63: 0.0132408 | R63: 0.0132408 | S63: 0.0132408 | T63: 0.0132408 | U63: 0.0132408 | V63: 0.0132408 | W63: 0.0132408 | X63: 0.0132408 | Y63: 0.0132408 | Z63: none
... A92: Calib_LoadFactor,date=2025-23-4T12:31:16+02:00 | B92: EU-15 | C92: trn_shipping_intl | D92: International Ship | E92: 1 | F92: 1 | G92: 1 | H92: 1 | I92: 1 | J92: 1 | K92: 1 | L92: 1 | M92: 1 | N92: 1 | O92: 1 | P92: 1 | Q92: 1 | R92: 1 | S92: 1 | T92: 1 | U92: 1 | V92: 1 | W92: 1 | X92: 1 | Y92: 1 | Z92: none
A95: 2. Data to be applied
A96: mode | B96: ctry | C96: 2015 | D96: 2020 | E96: 2050 | F96: GCAM_region_ID | G96: Unit
A97: NMT | B97: AUSTRIA | C97: 0.0692 | D97: 0.07 | E97: 0.1345 | F97: 13 | G97: Perc
A98: NMT | B98: BELGIUM | C98: 0.0523 | D98: 0.0562 | E98: 0.1345 | F98: 13 | G98: Perc
A99: NMT | B99: BULGARIA | C99: 0.0768 | D99: 0.0776 | E99: 0.0755 | F99: 12 | G99: Perc
A100: NMT | B100: CROATIA | C100: 0.074 | D100: 0.074 | E100: 0.0755 | F100: 12 | G100: Perc
A101: NMT | B101: CYPRUS | C101: 0.0426 | D101: 0.0436 | E101: 0.0437 | F101: 12 | G101: Perc
...

Sheet TRN-Modes-values-IntAv
A1: region | B1: {='TRN-Modes-computation'!J283:Q283} -> 2015 | C1: 2020 | D1: 2025 | E1: 2030 | F1: 2035 | G1: 2040 | H1: 2045 | I1: 2050 | J1: energy.final.demand
A2: {='TRN-Modes-computation'!I285:Q285} -> EU-12 | B2: 1 | C2: 1 | D2: 0.13131756 | E2: 0.13131756 | F2: 0.13131756 | G2: 0.13131756 | H2: 0.13131756 | I2: 0.13131756 | J2: trn_aviation_intl
A3: {='TRN-Modes-computation'!I289:Q289} -> EU-15 | B3: 1 | C3: 1 | D3: -1.5077826 | E3: -1.5077826 | F3: -1.5077826 | G3: -1.5077826 | H3: -1.5077826 | I3: -1.5077826 | J3: trn_aviation_intl

Sheet TRN-Modes-values-SW
A1: region | B1: mode | C1: 2015 | D1: 2020 | E1: 2025 | F1: 2030 | G1: 2035 | H1: 2040 | I1: 2045 | J1: 2050 | K1: tranSubsector
A2: EU-12 | B2: {='TRN-Modes-computation'!N304:V311} -> NMT - Cycling | C2: 0.0137751 | D2: 0.0137751 | E2: 0.019456605 | F2: 0.02513811 | G2: 0.030819615 | H2: 0.03650112 | I2: 0.042182626 | J2: 0.047864131 | K2: Cycle
A3: EU-12 | B3: NMT - Walking | C3: 0.403575 | D3: 0.403575 | E3: 0.57002849 | F3: 0.73648197 | G3: 0.90293546 | H3: 1.0693889 | I3: 1.2358424 | J3: 1.4022959 | K3: Walk
A4: EU-12 | B4: road - 4W | C4: 1 | D4: 1 | E4: 0.98016185 | F4: 0.96032371 | G4: 0.94048556 | H4: 0.92064741 | I4: 0.90080927 | J4: 0.88097112 | K4: 4W
A5: EU-12 | B5: road - 2-3W | C5: 0.012729 | D5: 0.012729 | E5: 0.01247648 | F5: 0.01222396 | G5: 0.011971441 | H5: 0.011718921 | I5: 0.011466401 | J5: 0.011213881 | K5: 2W and 3W
A6: EU-12 | B6: road - bus | C6: 0.388134 | D6: 0.388134 | E6: 0.38043414 | F6: 0.37273428 | G6: 0.36503442 | H6: 0.35733456 | I6: 0.3496347 | J6: 0.34193485 | K6: Bus
A7: EU-12 | B7: trains - HSR | C7: 0 | D7: 5.88235e-05 | E7: 7.2741666e-05 | F7: 8.6659831e-05 | G7: 0.000100578 | H7: 0.00011449616 | I7: 0.00012841433 | J7: 0.00014233249 | K7: HSR
A8: EU-12 | B8: trains - Pass Rail | C8: 0.0132408 | D8: 0.0132408 | E8: 0.016373692 | F8: 0.019506583 | G8: 0.022639475 | H8: 0.025772366 | I8: 0.028905258 | J8: 0.032038149 | K8: Passenger Rail
A9: EU-12 | B9: av - Dom Av | C9: 0.00149513 | D9: 0.00149513 | E9: 0.0012459417 | F9: 0.00099675333 | G9: 0.000747565 | H9: 0.00049837667 | I9: 0.00024918833 | J9: 0 | K9: Domestic Aviation
A10: EU-15 | B10: {='TRN-Modes-computation'!O320:W327} -> 0.0239487 | C10: 0.0239487 | D10: 0.044630741 | E10: 0.065312782 | F10: 0.085994823 | G10: 0.10667686 | H10: 0.12735891 | I10: 0.14804095 | J10: 6.1815859 | K10: Cycle
A11: EU-15 | B11: 0.701623 | C11: 0.701623 | D11: 1.307543 | E11: 1.913463 | F11: 2.5193829 | G11: 3.1253029 | H11: 3.7312229 | I11: 4.3371429 | J11: 6.1815859 | K11: Walk
A12: EU-15 | B12: 1 | C12: 1 | D12: 0.97960648 | E12: 0.95921296 | F12: 0.93881944 | G12: 0.91842592 | H12: 0.8980324 | I12: 0.87763888 | J12: 0.87763888 | K12: 4W
A13: EU-15 | B13: 0.0195251 | C13: 0.0195251 | D13: 0.019126914 | E13: 0.018728729 | F13: 0.018330543 | G13: 0.017932358 | H13: 0.017534172 | I13: 0.017135987 | J13: 0.87763888 | K13: 2W and 3W
A14: EU-15 | B14: 0.053004 | C14: 0.053004 | D14: 0.051923062 | E14: 0.050842124 | F14: 0.049761186 | G14: 0.048680248 | H14: 0.047599309 | I14: 0.046518371 | J14: 0.87763888 | K14: Bus
A15: EU-15 | B15: 0.0024111 | C15: 0.0023281 | D15: 0.0028738656 | E15: 0.0034196312 | F15: 0.0039653969 | G15: 0.0045111625 | H15: 0.0050569281 | I15: 0.0056026937 | J15: 2.406552 | K15: HSR
A16: EU-15 | B16: 0.0509949 | C16: 0.0509949 | D16: 0.062949397 | E16: 0.074903893 | F16: 0.08685839 | G16: 0.098812886 | H16: 0.11076738 | I16: 0.12272188 | J16: 2.406552 | K16: Passenger Rail
A17: EU-15 | B17: 0.0080731 | C17: 0.0080731 | D17: 0.0068096598 | E17: 0.0055462195 | F17: 0.0042827793 | G17: 0.0030193391 | H17: 0.0017558989 | I17: 0.00049245864 | J17: 0.060999942 | K17: Domestic Aviation

Sheet Sheet3
A1: mode | B1: year | C1: AUSTRIA | D1: BELGIUM | E1: BULGARIA | F1: CROATIA | G1: CYPRUS | H1: CZECH_REPUBLIC | I1: DENMARK | J1: ESTONIA | K1: FINLAND | L1: FRANCE | M1: GERMANY | N1: GREECE | O1: HUNGARY | P1: IRELAND | Q1: ITALY | R1: LATVIA | S1: LITHUANIA | T1: LUXEMBOURG | U1: MALTA | V1: NETHERLANDS | W1: POLAND | X1: PORTUGAL | Y1: ROMANIA | Z1: SLOVAKIA | AA1: SLOVENIA | AB1: SPAIN | AC1: SWEDEN
A2: international aviation | B2: 2050 | C2: 1250 | D2: 1257.6521 | E2: 1250 | F2: 1250 | G2: 8916.1863 | H2: 1250 | I2: 1428.9779 | J2: 1250 | K2: 1278.4051 | L2: 1256.1755 | M2: 1807.98 | N2: 2323.2013 | O2: 1250 | P2: 1577.3057 | Q2: 1300 | R2: 1250 | S2: 1250 | T2: 1996.4761 | U2: 7379.9109 | V2: 1857.2009 | W2: 1250 | X2: 1250 | Y2: 1250 | Z2: 1250 | AA2: 1250 | AB2: 1270.0435 | AC2: 502.69697
A3: total | B3: 2050 | C3: 13535 | D3: 10535.391 | E3: 13535 | F3: 13535 | G3: 18126.941 | H3: 13535 | I3: 13325.187 | J3: 13535 | K3: 13642.856 | L3: 13320.795 | M3: 13861.029 | N3: 13803.189 | O3: 13535 | P3: 13862.306 | Q3: 12881.147 | R3: 13535 | S3: 13535 | T3: 14281.476 | U3: 14443.666 | V3: 14142.201 | W3: 13535 | X3: 13614.45 | Y3: 13535 | Z3: 13535 | AA3: 13535 | AB3: 11308.252 | AC3: 11728.371
A4: international aviation | B4: 2020 | C4: 2528.6784 | D4: 2538.3926 | E4: 819.42737 | F4: 926.23752 | G4: 8916.1863 | H4: 888.52273 | I4: 3313.2847 | J4: 1211.5711 | K4: 3733.7435 | L4: 2821.1766 | M4: 2099.2023 | N4: 2452.9301 | O4: 576.37106 | P4: 5441.7471 | Q4: 2220.1222 | R4: 1814.3281 | S4: 941.49968 | T4: 7837.0065 | U4: 7379.9109 | V4: 7041.1479 | W4: 551.50017 | X4: 3278.2046 | Y4: 400.06381 | Z4: 256.56639 | AA4: 399.99028 | AB4: 2582.3807 | AC4: 910.17626
A5: total | B5: 2020 | C5: 15864.755 | D5: 14853.993 | E5: 12980.747 | F5: 8794.6974 | G5: 18180.536 | H5: 11824.792 | I5: 16627.879 | J5: 16234.741 | K5: 18713.489 | L5: 18197.008 | M5: 15453.745 | N5: 16019.859 | O5: 9612.3714 | P5: 18912.292 | Q5: 18512.977 | R5: 11355.07 | S5: 13752.798 | T5: 23699.292 | U5: 14471.428 | V5: 16346.825 | W5: 7713.9638 | X5: 13232.09 | Y5: 7783.0048 | Z5: 7482.3176 | AA5: 15309.814 | AB5: 11925.171 | AC5: 13604.447
A6: international aviation | B6: 2015 | C6: 2609.1854 | D6: 2605.9441 | E6: 793.34881 | F6: 896.53546 | G6: 9326.4275 | H6: 901.24183 | I6: 3410.2424 | J6: 1226.9271 | K6: 3760.8798 | L6: 2862.8982 | M6: 2129.5833 | N6: 2445.4751 | O6: 571.45734 | P6: 5830.8882 | Q6: 2168.631 | R6: 1742.1586 | S6: 900.35265 | T6: 8714.4032 | U6: 8508.8238 | V6: 7234.373 | W6: 544.3824 | X6: 3262.3949 | Y6: 389.14238 | Z6: 258.06432 | AA6: 406.2404 | AB6: 2620.9644 | AC6: 962.33719
A7: total | B7: 2015 | C7: 15480.325 | D7: 13667.614 | E7: 10997.154 | F7: 8448.5614 | G7: 18458.214 | H7: 11201.83 | I7: 16073.601 | J7: 13710.261 | K7: 18505.928 | L7: 17292.133 | M7: 15609.103 | N7: 15520.346 | O7: 9130.6439 | P7: 19379.808 | Q7: 17046.497 | R7: 10329.969 | S7: 10770.981 | T7: 24595.769 | U7: 15768.719 | V7: 17039.151 | W7: 7408.3476 | X7: 12979.756 | Y7: 6667.4545 | Z7: 7145.0948 | AA7: 15226.405 | AB7: 11187.081 | AC7: 14728.138

Sheet TRN-Modes-computation (2)
A1: MODES COMPUTATION
A3: 1. Data from GCAM (LoadFactor Hscen)
A4: transport service output by mode
A5: scenario | B5: region | C5: sector | D5: mode | E5: 1990 | F5: 2005 | G5: 2010 | H5: 2015 | I5: 2020 | J5: 2025 | K5: 2030 | L5: 2035 | M5: 2040 | N5: 2045 | O5: 2050 | P5: 2065 | Q5: 2080 | R5: 2095 | S5: Units
A6: Calib_LoadFactor2,date=2025-23-4T15:03:25+02:00 | B6: EU-12 | C6: trn_aviation_intl | D6: International Aviation | E6: 32280.9 | F6: 34737.6 | G6: 41232.1 | H6: 44763.7 | I6: 51256.8 | J6: 64214.1 | K6: 74527.6 | L6: 80476.646 | M6: 84871.663 | N6: 87862.98 | O6: 90269.441 | P6: 0 | Q6: 0 | R6: 0 | S6: million pass-km
A7: Calib_LoadFactor2,date=2025-23-4T15:03:25+02:00 | B7: EU-12 | C7: trn_freight | D7: Domestic Ship | E7: 70700.7 | F7: 13111.1 | G7: 17363.7 | H7: 15470.5 | I7: 18039.82 | J7: 21663.79 | K7: 26479.9 | L7: 32708.983 | M7: 36356.353 | N7: 38252.452 | O7: 39725.384 | P7: 0 | Q7: 0 | R7: 0 | S7: million ton-km
A8: Calib_LoadFactor2,date=2025-23-4T15:03:25+02:00 | B8: EU-12 | C8: trn_freight | D8: Freight Rail | E8: 262042.36 | F8: 198205.21 | G8: 175160.2 | H8: 164781.04 | I8: 183274.3 | J8: 203259.25 | K8: 200243.1 | L8: 178406.4 | M8: 171659.4 | N8: 175512.3 | O8: 181836.8 | P8: 0 | Q8: 0 | R8: 0 | S8: million ton-km
A9: Calib_LoadFactor2,date=2025-23-4T15:03:25+02:00 | B9: EU-12 | C9: trn_freight | D9: road | E9: 263310 | F9: 397360 | G9: 479298 | H9: 494165 | I9: 545552 | J9: 614375 | K9: 688784 | L9: 758104 | M9: 809231 | N9: 841914 | O9: 866222 | P9: 0 | Q9: 0 | R9: 0 | S9: million ton-km
A10: Calib_LoadFactor2,date=2025-23-4T15:03:25+02:00 | B10: EU-12 | C10: trn_freight_road | D10: Heavy truck | E10: 233530 | F10: 354422 | G10: 427651 | H10: 440708 | I10: 486585.21 | J10: 547583.21 | K10: 613347.86 | L10: 674826.58 | M10: 720337.52 | N10: 749169.94 | O10: 770004.83 | P10: 0 | Q10: 0 | R10: 0 | S10: million ton-km
A11: Calib_LoadFactor2,date=2025-23-4T15:03:25+02:00 | B11: EU-12 | C11: trn_freight_road | D11: Light truck | E11: 6938.53 | F11: 8895.31 | G11: 10510.8 | H11: 10995.6 | I11: 12126.703 | J11: 13721.919 | K11: 15470.392 | L11: 17081.814 | M11: 18235.023 | N11: 18968.25 | O11: 19542.919 | P11: 0 | Q11: 0 | R11: 0 | S11: million ton-km
A12: Calib_LoadFactor2,date=2025-23-4T15:03:25+02:00 | B12: EU-12 | C12: trn_freight_road | D12: Medium truck | E12: 22841.6 | F12: 34042.9 | G12: 41136.2 | H12: 42461.6 | I12: 46839.48 | J12: 53072.465 | K12: 59976.177 | L12: 66215.462 | M12: 70689.366 | N12: 73812.972 | O12: 76719.62 | P12: 0 | Q12: 0 | R12: 0 | S12: million ton-km
A13: Calib_LoadFactor2,date=2025-23-4T15:03:25+02:00 | B13: EU-12 | C13: trn_pass | D13: Cycle | E13: 17265.8 | F13: 16531.9 | G13: 16277.9 | H13: 16023.9 | I13: 14467.3 | J13: 12908.4 | K13: 11555.2 | L13: 10533.8 | M13: 9884.53 | N13: 9341.42 | O13: 8867.47 | P13: 0 | Q13: 0 | R13: 0 | S13: million pass-km
A14: Calib_LoadFactor2,date=2025-23-4T15:03:25+02:00 | B14: EU-12 | C14: trn_pass | D14: Domestic Aviation | E14: 5331.03 | F14: 5193.26 | G14: 5821.69 | H14: 6241.59 | I14: 7592.54 | J14: 10863.3 | K14: 13870.3 | L14: 15597.648 | M14: 17104.321 | N14: 18098.762 | O14: 18826.929 | P14: 0 | Q14: 0 | R14: 0 | S14: million pass-km
A15: Calib_LoadFactor2,date=2025-23-4T15:03:25+02:00 | B15: EU-12 | C15: trn_pass | D15: HSR | E15: 0 | F15: 0 | G15: 0 | H15: 0 | I15: 332.385 | J15: 872.175 | K15: 1538.51 | L15: 2331.1 | M15: 3182.59 | N15: 4189.79 | O15: 5365.01 | P15: 0 | Q15: 0 | R15: 0 | S15: million pass-km
A16: Calib_LoadFactor2,date=2025-23-4T15:03:25+02:00 | B16: EU-12 | C16: trn_pass | D16: Passenger Rail | E16: 88848.87 | F16: 70151.4 | G16: 61930.3 | H16: 57839.1 | I16: 61252.1 | J16: 65091.5 | K16: 65146.9 | L16: 64534 | M16: 63134.1 | N16: 62053.9 | O16: 61115.7 | P16: 0 | Q16: 0 | R16: 0 | S16: million pass-km
... A45: Calib_LoadFactor2,date=2025-23-4T15:03:25+02:00 | B45: EU-15 | C45: trn_shipping_intl | D45: International Ship | E45: 12346400 | F45: 18282500 | G45: 16574700 | H45: 14015900 | I45: 14055230 | J45: 14856130 | K45: 15426040 | L45: 16455167 | M45: 17170537 | N45: 17741282 | O45: 18312828 | P45: 0 | Q45: 0 | R45: 0 | S45: million ton-km
A47: income.elasticity | E47: 1990 | F47: 2005 | G47: 2010 | H47: 2015 | I47: 2020 | J47: 2025 | K47: 2030 | L47: 2035 | M47: 2040 | N47: 2045 | O47: 2050 | P47: 2065 | Q47: 2080 | R47: 2095 | S47: Units
B48: EU-12 | C48: trn_aviation_intl | D48: International Aviation | E48: 1 | F48: 1 | G48: 1 | H48: 1 | I48: 1 | J48: 1 | K48: 1 | L48: 1 | M48: 1 | N48: 1 | O48: 1 | S48: unitless
B49: EU-15 | C49: trn_aviation_intl | D49: International Aviation | E49: 1 | F49: 1 | G49: 1 | H49: 1 | I49: 1 | J49: 1 | K49: 1 | L49: 1 | M49: 1 | N49: 1 | O49: 1 | S49: unitless
A51: transport subsector share-weights
A52: scenario | B52: region | C52: sector | D52: subsector | E52: 1990 | F52: 2005 | G52: 2010 | H52: 2015 | I52: 2020 | J52: 2025 | K52: 2030 | L52: 2035 | M52: 2040 | N52: 2045 | O52: 2050 | P52: 2055 | Q52: 2060 | R52: 2065 | S52: 2070 | T52: 2075 | U52: 2080 | V52: 2085 | W52: 2090 | X52: 2095 | Y52: 2100 | Z52: Units
A53: Calib_LoadFactor,date=2025-23-4T12:31:16+02:00 | B53: EU-12 | C53: trn_aviation_intl | D53: International Aviation | E53: 1 | F53: 1 | G53: 1 | H53: 1 | I53: 1 | J53: 1 | K53: 1 | L53: 1 | M53: 1 | N53: 1 | O53: 1 | P53: 1 | Q53: 1 | R53: 1 | S53: 1 | T53: 1 | U53: 1 | V53: 1 | W53: 1 | X53: 1 | Y53: 1 | Z53: none
A54: Calib_LoadFactor,date=2025-23-4T12:31:16+02:00 | B54: EU-12 | C54: trn_freight | D54: Domestic Ship | E54: 0.000795575 | F54: 0.000114108 | G54: 0.000240711 | H54: 0.000229626 | I54: 0.000229626 | J54: 0.000229626 | K54: 0.000229626 | L54: 0.000229626 | M54: 0.000229626 | N54: 0.000229626 | O54: 0.000229626 | P54: 0.000229626 | Q54: 0.000229626 | R54: 0.000229626 | S54: 0.000229626 | T54: 0.000229626 | U54: 0.000229626 | V54: 0.000229626 | W54: 0.000229626 | X54: 0.000229626 | Y54: 0.000229626 | Z54: none
A55: Calib_LoadFactor,date=2025-23-4T12:31:16+02:00 | B55: EU-12 | C55: trn_freight | D55: Freight Rail | E55: 0.201544 | F55: 0.110995 | G55: 0.0710973 | H55: 0.062487 | I55: 0.062487 | J55: 0.062487 | K55: 0.062487 | L55: 0.062487 | M55: 0.062487 | N55: 0.062487 | O55: 0.062487 | P55: 0.062487 | Q55: 0.062487 | R55: 0.062487 | S55: 0.062487 | T55: 0.062487 | U55: 0.062487 | V55: 0.062487 | W55: 0.062487 | X55: 0.062487 | Y55: 0.062487 | Z55: none
A56: Calib_LoadFactor,date=2025-23-4T12:31:16+02:00 | B56: EU-12 | C56: trn_freight | D56: road | E56: 1 | F56: 1 | G56: 1 | H56: 1 | I56: 1 | J56: 1 | K56: 1 | L56: 1 | M56: 1 | N56: 1 | O56: 1 | P56: 1 | Q56: 1 | R56: 1 | S56: 1 | T56: 1 | U56: 1 | V56: 1 | W56: 1 | X56: 1 | Y56: 1 | Z56: none
A57: Calib_LoadFactor,date=2025-23-4T12:31:16+02:00 | B57: EU-12 | C57: trn_freight_road | D57: Heavy truck | E57: 1 | F57: 1 | G57: 1 | H57: 1 | I57: 1 | J57: 1 | K57: 1 | L57: 1 | M57: 1 | N57: 1 | O57: 1 | P57: 1 | Q57: 1 | R57: 1 | S57: 1 | T57: 1 | U57: 1 | V57: 1 | W57: 1 | X57: 1 | Y57: 1 | Z57: none
A58: Calib_LoadFactor,date=2025-23-4T12:31:16+02:00 | B58: EU-12 | C58: trn_freight_road | D58: Light truck | E58: 0.388042 | F58: 0.326507 | G58: 0.295752 | H58: 0.295565 | I58: 0.295565 | J58: 0.295565 | K58: 0.295565 | L58: 0.295565 | M58: 0.295565 | N58: 0.295565 | O58: 0.295565 | P58: 0.295565 | Q58: 0.295565 | R58: 0.295565 | S58: 0.295565 | T58: 0.295565 | U58: 0.295565 | V58: 0.295565 | W58: 0.295565 | X58: 0.295565 | Y58: 0.295565 | Z58: none
A59: Calib_LoadFactor,date=2025-23-4T12:31:16+02:00 | B59: EU-12 | C59: trn_freight_road | D59: Medium truck | E59: 0.499758 | F59: 0.488309 | G59: 0.461901 | H59: 0.457693 | I59: 0.457693 | J59: 0.457693 | K59: 0.457693 | L59: 0.457693 | M59: 0.457693 | N59: 0.457693 | O59: 0.457693 | P59: 0.457693 | Q59: 0.457693 | R59: 0.457693 | S59: 0.457693 | T59: 0.457693 | U59: 0.457693 | V59: 0.457693 | W59: 0.457693 | X59: 0.457693 | Y59: 0.457693 | Z59: none
A60: Calib_LoadFactor,date=2025-23-4T12:31:16+02:00 | B60: EU-12 | C60: trn_pass | D60: Cycle | E60: 0.0150988 | F60: 0.0140179 | G60: 0.0128294 | H60: 0.0137751 | I60: 0.0137751 | J60: 0.0137751 | K60: 0.0137751 | L60: 0.0137751 | M60: 0.0137751 | N60: 0.0137751 | O60: 0.0137751 | P60: 0.0137751 | Q60: 0.0137751 | R60: 0.0137751 | S60: 0.0137751 | T60: 0.0137751 | U60: 0.0137751 | V60: 0.0137751 | W60: 0.0137751 | X60: 0.0137751 | Y60: 0.0137751 | Z60: none
A61: Calib_LoadFactor,date=2025-23-4T12:31:16+02:00 | B61: EU-12 | C61: trn_pass | D61: Domestic Aviation | E61: 0.00257035 | F61: 0.00157745 | G61: 0.0015847 | H61: 0.00149513 | I61: 0.00149513 | J61: 0.00149513 | K61: 0.00149513 | L61: 0.00149513 | M61: 0.00149513 | N61: 0.00149513 | O61: 0.00149513 | P61: 0.00149513 | Q61: 0.00149513 | R61: 0.00149513 | S61: 0.00149513 | T61: 0.00149513 | U61: 0.00149513 | V61: 0.00149513 | W61: 0.00149513 | X61: 0.00149513 | Y61: 0.00149513 | Z61: none
A62: Calib_LoadFactor,date=2025-23-4T12:31:16+02:00 | B62: EU-12 | C62: trn_pass | D62: HSR | E62: 0 | F62: 0 | G62: 0 | H62: 0 | I62: 5.88235e-05 | J62: 0.000117647 | K62: 0.000176471 | L62: 0.000235294 | M62: 0.000294118 | N62: 0.000352941 | O62: 0.000411765 | P62: 0.000470588 | Q62: 0.000529412 | R62: 0.000588235 | S62: 0.000647059 | T62: 0.000705882 | U62: 0.000764706 | V62: 0.000823529 | W62: 0.000882353 | X62: 0.000941176 | Y62: 0.001 | Z62: none
A63: Calib_LoadFactor,date=2025-23-4T12:31:16+02:00 | B63: EU-12 | C63: trn_pass | D63: Passenger Rail | E63: 0.0353507 | F63: 0.020358 | G63: 0.0147021 | H63: 0.0132408 | I63: 0.0132408 | J63: 0.0132408 | K63: 0.0132408 | L63: 0.0132408 | M63: 0.0132408 | N63: 0.0132408 | O63: 0.0132408 | P63: 0.0132408 | Q63: 0.0132408 | R63: 0.0132408 | S63: 0.0132408 | T63: 0.0132408 | U63: 0.0132408 | V63: 0.0132408 | W63: 0.0132408 | X63: 0.0132408 | Y63: 0.0132408 | Z63: none
... A92: Calib_LoadFactor,date=2025-23-4T12:31:16+02:00 | B92: EU-15 | C92: trn_shipping_intl | D92: International Ship | E92: 1 | F92: 1 | G92: 1 | H92: 1 | I92: 1 | J92: 1 | K92: 1 | L92: 1 | M92: 1 | N92: 1 | O92: 1 | P92: 1 | Q92: 1 | R92: 1 | S92: 1 | T92: 1 | U92: 1 | V92: 1 | W92: 1 | X92: 1 | Y92: 1 | Z92: none
A95: 2. Data to be applied
A96: mode | B96: ctry | C96: 2015 | D96: 2020 | E96: 2050 | F96: GCAM_region_ID | G96: Unit
A97: NMT | B97: AUSTRIA | C97: 0.0692 | D97: 0.07 | E97: 0.1345 | F97: 13 | G97: Perc
A98: NMT | B98: BELGIUM | C98: 0.0523 | D98: 0.0562 | E98: 0.1345 | F98: 13 | G98: Perc
A99: NMT | B99: BULGARIA | C99: 0.0768 | D99: 0.0776 | E99: 0.0755 | F99: 12 | G99: Perc
A100: NMT | B100: CROATIA | C100: 0.074 | D100: 0.074 | E100: 0.0755 | F100: 12 | G100: Perc
A101: NMT | B101: CYPRUS | C101: 0.0426 | D101: 0.0436 | E101: 0.0437 | F101: 12 | G101: Perc
...

Sheet BLD-FloorSpace-computation
A1: 1. Data to be applied
A2: ctry | B2: region | C2: year | D2: m2.person | E2: person | F2: bnm2
A3: Austria | B3: EU-15 | C3: 2015 | D3: 43.875352 | E3: 8678.66 | F3: 0.00038077927
A4: Austria | B4: EU-15 | C4: 2020 | D4: 43.875352 | E4: 8998.6184 | F4: 0.00039481755
A5: Austria | B5: EU-15 | C5: 2050 | D5: 43.875352 | E5: 9367.4646 | F5: 0.00041100081
A6: Belgium | B6: EU-15 | C6: 2015 | D6: 50.453166 | E6: 11287.94 | F6: 0.00056951231
A7: Belgium | B7: EU-15 | C7: 2020 | D7: 49.931318 | E7: 11616.761 | F7: 0.00058004018
A8: Belgium | B8: EU-15 | C8: 2050 | D8: 51.052595 | E8: 12423.407 | F8: 0.00063424715
A9: Bulgaria | B9: EU-12 | C9: 2015 | D9: 31.005212 | E9: 7199.741 | F9: 0.00022322949
A10: Bulgaria | B10: EU-12 | C10: 2020 | D10: 32.290182 | E10: 6884.793 | F10: 0.00022231122
A11: Bulgaria | B11: EU-12 | C11: 2050 | D11: 40 | E11: 5450.9013 | F11: 0.00021803605
A12: Croatia | B12: EU-12 | C12: 2015 | D12: 30.199092 | E12: 4232.874 | F12: 0.00012782895
A13: Croatia | B13: EU-12 | C13: 2020 | D13: 31.599222 | E13: 4077.9567 | F13: 0.00012886026
A14: Croatia | B14: EU-12 | C14: 2050 | D14: 40 | E14: 3358.9859 | F14: 0.00013435944
... A83: Sweden | B83: EU-15 | C83: 2050 | D83: 47.443469 | E83: 11663.136 | F83: 0.00055333962
A86: 2. Average values by GCAM region
A87: GCAM_region_name | C87: 2015 | D87: 2020 | E87: 2050 | F87: Unit
A88: EU-12 | C88: =SUMIFS($D$1:$D$83, $B$1:$B$83, $A$88, $C$1:$C$83, C$87) -> 423.33651 | D88: =SUMIFS($D$1:$D$83, $B$1:$B$83, $A$88, $C$1:$C$83, D$87) -> 440.28394 | E88: =SUMIFS($D$1:$D$83, $B$1:$B$83, $A$88, $C$1:$C$83, E$87) -> 541.96846 | F88: bn m2
A89: EU-15 | C89: =SUMIFS($D$1:$D$83, $B$1:$B$83, $A$89, $C$1:$C$83, C$87) -> 631.53432 | D89: =SUMIFS($D$1:$D$83, $B$1:$B$83, $A$89, $C$1:$C$83, D$87) -> 632.38642 | E89: =SUMIFS($D$1:$D$83, $B$1:$B$83, $A$89, $C$1:$C$83, E$87) -> 635.94353 | F89: bn m2
